Workbook

Sheet FinalOutput
A1: PK | B1: Route | C1: Location Description | D1: From | E1: To | F1: From RP | G1: To RP | H1: PvmtArea | I1: RC | J1: FA | K1: Planned Project | L1: # Lanes | M1: Surf Type | N1: NHS | O1: Sub | P1: Unit | Q1: County | R1: AADT | S1: AADTT | T1: Chipable | U1: Replacement cycle (years) | V1: Adjusted Replacement cycle (years) | W1: Year of latest project completion | X1: 20y Project plan 1 | Y1: 20y Project plan 2 | Z1: 20y Project plan 3 | AA1: 20y Project plan 4 | AB1: 20y Project plan 5 | AC1: 20y chip seal 3rd phase plan | AD1: Planned rpm project by David | AE1: 20y Project plan 1_description | AF1: 20y Project plan 2_description | AG1: 20y Project plan 3_description | AH1: 20y Project plan 4_description | AI1: 20y Project plan 5_description | AJ1: 20y Chip Seal Plan | AK1: Davids's plan for rpm replacement | AL1: replacement due | AM1: Possible integration with planned projects year | AN1: Possible integrated planned projects
A2: 60000 | B2: US 50 | C2: From US 150 to SR 60 | D2: 43.289583 | E2: 53.424868 | F2: 43 +0.223 | G2: 53 +0.372 | H2: 167677 | I2: C1 | J2: 20 | K2: 2026 | L2: 2 | M2: FLEX | N2: Is on the NHS | O2: Paoli,Vincennes | P2: Bedford Unit 3,Loogootee Unit | Q2: Lawrence,Martin,Orange | R2: 3656 | S2: 986 | T2: N/A | U2: =IF($L2<=2, IF($R2<=RpmDesignStandard!$C$2,RpmDesignStandard!$D$2, IF(AND($R2>RpmDesignStandard!$B$3,$R2<=RpmDesignStandard!$C$3),RpmDesignStandard!$D$3,RpmDesignStandard!$D$4)), IF($R2<=RpmDesignStandard!$C$5, RpmDesignStandard!$D$5, IF(AND($R2>RpmDesignStandard!$B$6,$R2<=RpmDesignStandard!$C$6),RpmDesignStandard!$D$6, IF(AND($R2>RpmDesignStandard!$B$7,$R2<=RpmDesignStandard!$C$7),RpmDesignStandard!$D$7,RpmDesignStandard!$D$8)))) -> 4 | V2: =U2*RpmDesignStandard!$H$1 -> 8 | W2: =VLOOKUP(A2,RPM_ProjectRecord!A:AB,8,FALSE) | X2: =IFERROR(VALUE(LEFT(AE2,4)),"") | Y2: =IFERROR(VALUE(LEFT(AF2,4)),"") | Z2: =IFERROR(VALUE(LEFT(AG2,4)),"") | AA2: =IFERROR(VALUE(LEFT(AH2,4)),"") | AB2: =IFERROR(VALUE(LEFT(AI2,4)),"") | AC2: =IF(VLOOKUP(A2,'3rdPhaseChipSeal'!A:L,12,FALSE)="","",VLOOKUP(A2,'3rdPhaseChipSeal'!A:L,12,FALSE)) | AD2: =IFERROR(IF(VLOOKUP(A2,RpmContracts!A:C,3,FALSE)="","",VLOOKUP(A2,RpmContracts!A:C,3,FALSE)),"") -> 2027 | AE2: =IF(VLOOKUP(A2,'20yPlan'!A:B,2,FALSE)="","",VLOOKUP(A2,'20yPlan'!A:B,2,FALSE)) | AF2: =IF(VLOOKUP(A2,'20yPlan'!A:C,3,FALSE)="","",VLOOKUP(A2,'20yPlan'!A:C,3,FALSE)) | AG2: =IF(VLOOKUP(A2,'20yPlan'!A:D,4,FALSE)="","",VLOOKUP(A2,'20yPlan'!A:D,4,FALSE)) | AH2: =IF(VLOOKUP(A2,'20yPlan'!A:E,5,FALSE)="","",VLOOKUP(A2,'20yPlan'!A:E,5,FALSE)) | AI2: =IF(VLOOKUP(A2,'20yPlan'!A:F,6,FALSE)="","",VLOOKUP(A2,'20yPlan'!A:F,6,FALSE)) | AJ2: =IF(AC2="","",_xlfn.CONCAT(AC2," ","Chip Seal")) | AK2: =IF(AD2="","",_xlfn.CONCAT(AD2," ","RPM Replacement")) -> 2027 RPM Replacement | AL2: =IFERROR(U2+W2,YEAR(TODAY())) -> 2025 | AM2: =IF(W2="",AD2,IF(AND(MIN(X2:AD2)<=(W2+V2),MIN(X2:AD2)>W2),MIN(X2:AD2),"")) -> 2027 | AN2: =IF(AM2=X2,AE2,IF(AM2=Y2,AF2,IF(AM2=AC2,AJ2,AK2))) -> 2027 RPM Replacement
A3: 60001 | B3: I-64 | C3: From Illinois State Line to 0.6 mile W of SR 165 (Bridge Over Flat Run Ditch) | D3: 0 | E3: 11.296388 | F3: 0 +0.000 | G3: 11 +0.272 | H3: 544122 | I3: A2 | J3: 4 | K3: 2036 | L3: 4 | M3: FLEX | N3: Is on the NHS | O3: Evansville,Vincennes | P3: Oakland City Unit,Poseyville Unit 3 | Q3: Gibson,Posey | R3: 14526 | S3: 6148 | T3: N/A | U3: =IF($L3<=2, IF($R3<=RpmDesignStandard!$C$2,RpmDesignStandard!$D$2, IF(AND($R3>RpmDesignStandard!$B$3,$R3<=RpmDesignStandard!$C$3),RpmDesignStandard!$D$3,RpmDesignStandard!$D$4)), IF($R3<=RpmDesignStandard!$C$5, RpmDesignStandard!$D$5, IF(AND($R3>RpmDesignStandard!$B$6,$R3<=RpmDesignStandard!$C$6),RpmDesignStandard!$D$6, IF(AND($R3>RpmDesignStandard!$B$7,$R3<=RpmDesignStandard!$C$7),RpmDesignStandard!$D$7,RpmDesignStandard!$D$8)))) -> 3 | V3: =U3*RpmDesignStandard!$H$1 -> 6 | W3: =VLOOKUP(A3,RPM_ProjectRecord!A:AB,8,FALSE) | X3: =IFERROR(VALUE(LEFT(AE3,4)),"") -> 2036 | Y3: =IFERROR(VALUE(LEFT(AF3,4)),"") | Z3: =IFERROR(VALUE(LEFT(AG3,4)),"") | AA3: =IFERROR(VALUE(LEFT(AH3,4)),"") | AB3: =IFERROR(VALUE(LEFT(AI3,4)),"") | AC3: =IF(VLOOKUP(A3,'3rdPhaseChipSeal'!A:L,12,FALSE)="","",VLOOKUP(A3,'3rdPhaseChipSeal'!A:L,12,FALSE)) | AD3: =IFERROR(IF(VLOOKUP(A3,RpmContracts!A:C,3,FALSE)="","",VLOOKUP(A3,RpmContracts!A:C,3,FALSE)),"") -> 2027 | AE3: =IF(VLOOKUP(A3,'20yPlan'!A:B,2,FALSE)="","",VLOOKUP(A3,'20yPlan'!A:B,2,FALSE)) -> 2036 Preventive Maintenance | AF3: =IF(VLOOKUP(A3,'20yPlan'!A:C,3,FALSE)="","",VLOOKUP(A3,'20yPlan'!A:C,3,FALSE)) | AG3: =IF(VLOOKUP(A3,'20yPlan'!A:D,4,FALSE)="","",VLOOKUP(A3,'20yPlan'!A:D,4,FALSE)) | AH3: =IF(VLOOKUP(A3,'20yPlan'!A:E,5,FALSE)="","",VLOOKUP(A3,'20yPlan'!A:E,5,FALSE)) | AI3: =IF(VLOOKUP(A3,'20yPlan'!A:F,6,FALSE)="","",VLOOKUP(A3,'20yPlan'!A:F,6,FALSE)) | AJ3: =IF(AC3="","",_xlfn.CONCAT(AC3," ","Chip Seal")) | AK3: =IF(AD3="","",_xlfn.CONCAT(AD3," ","RPM Replacement")) -> 2027 RPM Replacement | AL3: =IFERROR(U3+W3,YEAR(TODAY())) -> 2025 | AM3: =IF(W3="",AD3,IF(AND(MIN(X3:AD3)<=(W3+V3),MIN(X3:AD3)>W3),MIN(X3:AD3),"")) -> 2027 | AN3: =IF(AM3=X3,AE3,IF(AM3=Y3,AF3,IF(AM3=AC3,AJ3,AK3))) -> 2027 RPM Replacement
A4: 60002 | B4: I-64 | C4: From 0.6 mile W of SR 165 (Bridge Over Flat Run Ditch) to 3.32 mi E of SR 65 | D4: 11.296388 | E4: 20.964243 | F4: 11 +0.272 | G4: 20 +0.988 | H4: 467255 | I4: A2 | J4: 3 | K4: 2036 | L4: 4 | M4: FLEX | N4: Is on the NHS | O4: Evansville | P4: Boyle Lane Unit 2,Poseyville Unit 3 | Q4: Gibson,Posey,Vanderburgh | R4: 15003 | S4: 4991 | T4: N/A | U4: =IF($L4<=2, IF($R4<=RpmDesignStandard!$C$2,RpmDesignStandard!$D$2, IF(AND($R4>RpmDesignStandard!$B$3,$R4<=RpmDesignStandard!$C$3),RpmDesignStandard!$D$3,RpmDesignStandard!$D$4)), IF($R4<=RpmDesignStandard!$C$5, RpmDesignStandard!$D$5, IF(AND($R4>RpmDesignStandard!$B$6,$R4<=RpmDesignStandard!$C$6),RpmDesignStandard!$D$6, IF(AND($R4>RpmDesignStandard!$B$7,$R4<=RpmDesignStandard!$C$7),RpmDesignStandard!$D$7,RpmDesignStandard!$D$8)))) -> 3 | V4: =U4*RpmDesignStandard!$H$1 -> 6 | W4: =VLOOKUP(A4,RPM_ProjectRecord!A:AB,8,FALSE) | X4: =IFERROR(VALUE(LEFT(AE4,4)),"") -> 2036 | Y4: =IFERROR(VALUE(LEFT(AF4,4)),"") | Z4: =IFERROR(VALUE(LEFT(AG4,4)),"") | AA4: =IFERROR(VALUE(LEFT(AH4,4)),"") | AB4: =IFERROR(VALUE(LEFT(AI4,4)),"") | AC4: =IF(VLOOKUP(A4,'3rdPhaseChipSeal'!A:L,12,FALSE)="","",VLOOKUP(A4,'3rdPhaseChipSeal'!A:L,12,FALSE)) | AD4: =IFERROR(IF(VLOOKUP(A4,RpmContracts!A:C,3,FALSE)="","",VLOOKUP(A4,RpmContracts!A:C,3,FALSE)),"") -> 2027 | AE4: =IF(VLOOKUP(A4,'20yPlan'!A:B,2,FALSE)="","",VLOOKUP(A4,'20yPlan'!A:B,2,FALSE)) -> 2036 Preventive Maintenance | AF4: =IF(VLOOKUP(A4,'20yPlan'!A:C,3,FALSE)="","",VLOOKUP(A4,'20yPlan'!A:C,3,FALSE)) | AG4: =IF(VLOOKUP(A4,'20yPlan'!A:D,4,FALSE)="","",VLOOKUP(A4,'20yPlan'!A:D,4,FALSE)) | AH4: =IF(VLOOKUP(A4,'20yPlan'!A:E,5,FALSE)="","",VLOOKUP(A4,'20yPlan'!A:E,5,FALSE)) | AI4: =IF(VLOOKUP(A4,'20yPlan'!A:F,6,FALSE)="","",VLOOKUP(A4,'20yPlan'!A:F,6,FALSE)) | AJ4: =IF(AC4="","",_xlfn.CONCAT(AC4," ","Chip Seal")) | AK4: =IF(AD4="","",_xlfn.CONCAT(AD4," ","RPM Replacement")) -> 2027 RPM Replacement | AL4: =IFERROR(U4+W4,YEAR(TODAY())) -> 2025 | AM4: =IF(W4="",AD4,IF(AND(MIN(X4:AD4)<=(W4+V4),MIN(X4:AD4)>W4),MIN(X4:AD4),"")) -> 2027 | AN4: =IF(AM4=X4,AE4,IF(AM4=Y4,AF4,IF(AM4=AC4,AJ4,AK4))) -> 2027 RPM Replacement
A5: 60003 | B5: I-64 | C5: From 3.32 mi E of SR 65 to 0.5 mi E of US 41 | D5: 20.964243 | E5: 25.540208 | F5: 20 +0.988 | G5: 25 +0.524 | H5: 213562 | I5: A2 | J5: 8 | K5: 2034 | L5: 4 | M5: FLEX | N5: Is on the NHS | O5: Evansville | P5: Boyle Lane Unit 2 | Q5: Gibson,Vanderburgh | R5: 15539 | S5: 6135 | T5: N/A | U5: =IF($L5<=2, IF($R5<=RpmDesignStandard!$C$2,RpmDesignStandard!$D$2, IF(AND($R5>RpmDesignStandard!$B$3,$R5<=RpmDesignStandard!$C$3),RpmDesignStandard!$D$3,RpmDesignStandard!$D$4)), IF($R5<=RpmDesignStandard!$C$5, RpmDesignStandard!$D$5, IF(AND($R5>RpmDesignStandard!$B$6,$R5<=RpmDesignStandard!$C$6),RpmDesignStandard!$D$6, IF(AND($R5>RpmDesignStandard!$B$7,$R5<=RpmDesignStandard!$C$7),RpmDesignStandard!$D$7,RpmDesignStandard!$D$8)))) -> 3 | V5: =U5*RpmDesignStandard!$H$1 -> 6 | W5: =VLOOKUP(A5,RPM_ProjectRecord!A:AB,8,FALSE) | X5: =IFERROR(VALUE(LEFT(AE5,4)),"") -> 2034 | Y5: =IFERROR(VALUE(LEFT(AF5,4)),"") | Z5: =IFERROR(VALUE(LEFT(AG5,4)),"") | AA5: =IFERROR(VALUE(LEFT(AH5,4)),"") | AB5: =IFERROR(VALUE(LEFT(AI5,4)),"") | AC5: =IF(VLOOKUP(A5,'3rdPhaseChipSeal'!A:L,12,FALSE)="","",VLOOKUP(A5,'3rdPhaseChipSeal'!A:L,12,FALSE)) | AD5: =IFERROR(IF(VLOOKUP(A5,RpmContracts!A:C,3,FALSE)="","",VLOOKUP(A5,RpmContracts!A:C,3,FALSE)),"") -> 2027 | AE5: =IF(VLOOKUP(A5,'20yPlan'!A:B,2,FALSE)="","",VLOOKUP(A5,'20yPlan'!A:B,2,FALSE)) -> 2034 Preventive Maintenance | AF5: =IF(VLOOKUP(A5,'20yPlan'!A:C,3,FALSE)="","",VLOOKUP(A5,'20yPlan'!A:C,3,FALSE)) | AG5: =IF(VLOOKUP(A5,'20yPlan'!A:D,4,FALSE)="","",VLOOKUP(A5,'20yPlan'!A:D,4,FALSE)) | AH5: =IF(VLOOKUP(A5,'20yPlan'!A:E,5,FALSE)="","",VLOOKUP(A5,'20yPlan'!A:E,5,FALSE)) | AI5: =IF(VLOOKUP(A5,'20yPlan'!A:F,6,FALSE)="","",VLOOKUP(A5,'20yPlan'!A:F,6,FALSE)) | AJ5: =IF(AC5="","",_xlfn.CONCAT(AC5," ","Chip Seal")) | AK5: =IF(AD5="","",_xlfn.CONCAT(AD5," ","RPM Replacement")) -> 2027 RPM Replacement | AL5: =IFERROR(U5+W5,YEAR(TODAY())) -> 2025 | AM5: =IF(W5="",AD5,IF(AND(MIN(X5:AD5)<=(W5+V5),MIN(X5:AD5)>W5),MIN(X5:AD5),"")) -> 2027 | AN5: =IF(AM5=X5,AE5,IF(AM5=Y5,AF5,IF(AM5=AC5,AJ5,AK5))) -> 2027 RPM Replacement
A6: 60004 | B6: I-64 | C6: From 0.5 mi E of US 41 to 0.41 mi E of I-69 | D6: 25.540208 | E6: 29.848815 | F6: 25 +0.524 | G6: 29 +0.888 | H6: 208325 | I6: A2 | J6: 11 | K6: 2025 | L6: 4 | M6: FLEX | N6: Is on the NHS | O6: Evansville | P6: Boyle Lane Unit 2,Chandler Unit 4 | Q6: Gibson,Vanderburgh,Warrick | R6: 19060 | S6: 12948 | T6: N/A | U6: =IF($L6<=2, IF($R6<=RpmDesignStandard!$C$2,RpmDesignStandard!$D$2, IF(AND($R6>RpmDesignStandard!$B$3,$R6<=RpmDesignStandard!$C$3),RpmDesignStandard!$D$3,RpmDesignStandard!$D$4)), IF($R6<=RpmDesignStandard!$C$5, RpmDesignStandard!$D$5, IF(AND($R6>RpmDesignStandard!$B$6,$R6<=RpmDesignStandard!$C$6),RpmDesignStandard!$D$6, IF(AND($R6>RpmDesignStandard!$B$7,$R6<=RpmDesignStandard!$C$7),RpmDesignStandard!$D$7,RpmDesignStandard!$D$8)))) -> 3 | V6: =U6*RpmDesignStandard!$H$1 -> 6 | W6: =VLOOKUP(A6,RPM_ProjectRecord!A:AB,8,FALSE) | X6: =IFERROR(VALUE(LEFT(AE6,4)),"") -> 2039 | Y6: =IFERROR(VALUE(LEFT(AF6,4)),"") | Z6: =IFERROR(VALUE(LEFT(AG6,4)),"") | AA6: =IFERROR(VALUE(LEFT(AH6,4)),"") | AB6: =IFERROR(VALUE(LEFT(AI6,4)),"") | AC6: =IF(VLOOKUP(A6,'3rdPhaseChipSeal'!A:L,12,FALSE)="","",VLOOKUP(A6,'3rdPhaseChipSeal'!A:L,12,FALSE)) | AD6: =IFERROR(IF(VLOOKUP(A6,RpmContracts!A:C,3,FALSE)="","",VLOOKUP(A6,RpmContracts!A:C,3,FALSE)),"") -> 2027 | AE6: =IF(VLOOKUP(A6,'20yPlan'!A:B,2,FALSE)="","",VLOOKUP(A6,'20yPlan'!A:B,2,FALSE)) -> 2039 Minor Structural | AF6: =IF(VLOOKUP(A6,'20yPlan'!A:C,3,FALSE)="","",VLOOKUP(A6,'20yPlan'!A:C,3,FALSE)) | AG6: =IF(VLOOKUP(A6,'20yPlan'!A:D,4,FALSE)="","",VLOOKUP(A6,'20yPlan'!A:D,4,FALSE)) | AH6: =IF(VLOOKUP(A6,'20yPlan'!A:E,5,FALSE)="","",VLOOKUP(A6,'20yPlan'!A:E,5,FALSE)) | AI6: =IF(VLOOKUP(A6,'20yPlan'!A:F,6,FALSE)="","",VLOOKUP(A6,'20yPlan'!A:F,6,FALSE)) | AJ6: =IF(AC6="","",_xlfn.CONCAT(AC6," ","Chip Seal")) | AK6: =IF(AD6="","",_xlfn.CONCAT(AD6," ","RPM Replacement")) -> 2027 RPM Replacement | AL6: =IFERROR(U6+W6,YEAR(TODAY())) -> 2025 | AM6: =IF(W6="",AD6,IF(AND(MIN(X6:AD6)<=(W6+V6),MIN(X6:AD6)>W6),MIN(X6:AD6),"")) -> 2027 | AN6: =IF(AM6=X6,AE6,IF(AM6=Y6,AF6,IF(AM6=AC6,AJ6,AK6))) -> 2027 RPM Replacement
A7: 60005 | B7: I-64 | C7: From 0.41 mi E of I-69 to 0.13 mi E of SR 61 | D7: 29.848815 | E7: 39.713038 | F7: 29 +0.888 | G7: 39 +0.732 | H7: 469394 | I7: A2 | J7: 9 | K7: 2030 | L7: 4 | M7: FLEX | N7: Is on the NHS | O7: Evansville,Tell City,Vincennes | P7: Boyle Lane Unit 2,Chandler Unit 4,Dale Unit 4,Oakland City Unit | Q7: Gibson,Warrick | R7: 17394 | S7: 6116 | T7: N/A | U7: =IF($L7<=2, IF($R7<=RpmDesignStandard!$C$2,RpmDesignStandard!$D$2, IF(AND($R7>RpmDesignStandard!$B$3,$R7<=RpmDesignStandard!$C$3),RpmDesignStandard!$D$3,RpmDesignStandard!$D$4)), IF($R7<=RpmDesignStandard!$C$5, RpmDesignStandard!$D$5, IF(AND($R7>RpmDesignStandard!$B$6,$R7<=RpmDesignStandard!$C$6),RpmDesignStandard!$D$6, IF(AND($R7>RpmDesignStandard!$B$7,$R7<=RpmDesignStandard!$C$7),RpmDesignStandard!$D$7,RpmDesignStandard!$D$8)))) -> 3 | V7: =U7*RpmDesignStandard!$H$1 -> 6 | W7: =VLOOKUP(A7,RPM_ProjectRecord!A:AB,8,FALSE) | X7: =IFERROR(VALUE(LEFT(AE7,4)),"") -> 2030 | Y7: =IFERROR(VALUE(LEFT(AF7,4)),"") | Z7: =IFERROR(VALUE(LEFT(AG7,4)),"") | AA7: =IFERROR(VALUE(LEFT(AH7,4)),"") | AB7: =IFERROR(VALUE(LEFT(AI7,4)),"") | AC7: =IF(VLOOKUP(A7,'3rdPhaseChipSeal'!A:L,12,FALSE)="","",VLOOKUP(A7,'3rdPhaseChipSeal'!A:L,12,FALSE)) | AD7: =IFERROR(IF(VLOOKUP(A7,RpmContracts!A:C,3,FALSE)="","",VLOOKUP(A7,RpmContracts!A:C,3,FALSE)),"") -> 2027 | AE7: =IF(VLOOKUP(A7,'20yPlan'!A:B,2,FALSE)="","",VLOOKUP(A7,'20yPlan'!A:B,2,FALSE)) -> 2030 Minor Structural | AF7: =IF(VLOOKUP(A7,'20yPlan'!A:C,3,FALSE)="","",VLOOKUP(A7,'20yPlan'!A:C,3,FALSE)) | AG7: =IF(VLOOKUP(A7,'20yPlan'!A:D,4,FALSE)="","",VLOOKUP(A7,'20yPlan'!A:D,4,FALSE)) | AH7: =IF(VLOOKUP(A7,'20yPlan'!A:E,5,FALSE)="","",VLOOKUP(A7,'20yPlan'!A:E,5,FALSE)) | AI7: =IF(VLOOKUP(A7,'20yPlan'!A:F,6,FALSE)="","",VLOOKUP(A7,'20yPlan'!A:F,6,FALSE)) | AJ7: =IF(AC7="","",_xlfn.CONCAT(AC7," ","Chip Seal")) | AK7: =IF(AD7="","",_xlfn.CONCAT(AD7," ","RPM Replacement")) -> 2027 RPM Replacement | AL7: =IFERROR(U7+W7,YEAR(TODAY())) -> 2025 | AM7: =IF(W7="",AD7,IF(AND(MIN(X7:AD7)<=(W7+V7),MIN(X7:AD7)>W7),MIN(X7:AD7),"")) -> 2027 | AN7: =IF(AM7=X7,AE7,IF(AM7=Y7,AF7,IF(AM7=AC7,AJ7,AK7))) -> 2027 RPM Replacement
A8: 60006 | B8: I-64 | C8: From 0.13 mile E of SR 61 to 1.91 mile W SR 161 Overpass | D8: 39.713038 | E8: 48.674881 | F8: 39 +0.732 | G8: 48 +0.702 | H8: 437846 | I8: A2 | J8: 1 | K8: 2038 | L8: 4 | M8: FLEX | N8: Is on the NHS | O8: Tell City | P8: Chrisney Unit 5,Dale Unit 4 | Q8: Spencer,Warrick | R8: 17458 | S8: 6486 | T8: N/A | U8: =IF($L8<=2, IF($R8<=RpmDesignStandard!$C$2,RpmDesignStandard!$D$2, IF(AND($R8>RpmDesignStandard!$B$3,$R8<=RpmDesignStandard!$C$3),RpmDesignStandard!$D$3,RpmDesignStandard!$D$4)), IF($R8<=RpmDesignStandard!$C$5, RpmDesignStandard!$D$5, IF(AND($R8>RpmDesignStandard!$B$6,$R8<=RpmDesignStandard!$C$6),RpmDesignStandard!$D$6, IF(AND($R8>RpmDesignStandard!$B$7,$R8<=RpmDesignStandard!$C$7),RpmDesignStandard!$D$7,RpmDesignStandard!$D$8)))) -> 3 | V8: =U8*RpmDesignStandard!$H$1 -> 6 | W8: =VLOOKUP(A8,RPM_ProjectRecord!A:AB,8,FALSE) -> 2022 | X8: =IFERROR(VALUE(LEFT(AE8,4)),"") -> 2038 | Y8: =IFERROR(VALUE(LEFT(AF8,4)),"") | Z8: =IFERROR(VALUE(LEFT(AG8,4)),"") | AA8: =IFERROR(VALUE(LEFT(AH8,4)),"") | AB8: =IFERROR(VALUE(LEFT(AI8,4)),"") | AC8: =IF(VLOOKUP(A8,'3rdPhaseChipSeal'!A:L,12,FALSE)="","",VLOOKUP(A8,'3rdPhaseChipSeal'!A:L,12,FALSE)) | AD8: =IFERROR(IF(VLOOKUP(A8,RpmContracts!A:C,3,FALSE)="","",VLOOKUP(A8,RpmContracts!A:C,3,FALSE)),"") -> 2027 | AE8: =IF(VLOOKUP(A8,'20yPlan'!A:B,2,FALSE)="","",VLOOKUP(A8,'20yPlan'!A:B,2,FALSE)) -> 2038 Preventive Maintenance | AF8: =IF(VLOOKUP(A8,'20yPlan'!A:C,3,FALSE)="","",VLOOKUP(A8,'20yPlan'!A:C,3,FALSE)) | AG8: =IF(VLOOKUP(A8,'20yPlan'!A:D,4,FALSE)="","",VLOOKUP(A8,'20yPlan'!A:D,4,FALSE)) | AH8: =IF(VLOOKUP(A8,'20yPlan'!A:E,5,FALSE)="","",VLOOKUP(A8,'20yPlan'!A:E,5,FALSE)) | AI8: =IF(VLOOKUP(A8,'20yPlan'!A:F,6,FALSE)="","",VLOOKUP(A8,'20yPlan'!A:F,6,FALSE)) | AJ8: =IF(AC8="","",_xlfn.CONCAT(AC8," ","Chip Seal")) | AK8: =IF(AD8="","",_xlfn.CONCAT(AD8," ","RPM Replacement")) -> 2027 RPM Replacement | AL8: =IFERROR(U8+W8,YEAR(TODAY())) -> 2025 | AM8: =IF(W8="",AD8,IF(AND(MIN(X8:AD8)<=(W8+V8),MIN(X8:AD8)>W8),MIN(X8:AD8),"")) -> 2027 | AN8: =IF(AM8=X8,AE8,IF(AM8=Y8,AF8,IF(AM8=AC8,AJ8,AK8))) -> 2027 RPM Replacement
A9: 60007 | B9: I-64 | C9: From 1.91 mile W SR 161 Overpass to 0.79 Miles E of US 231 | D9: 48.674881 | E9: 57.249264 | F9: 48 +0.702 | G9: 57 +0.254 | H9: 405427 | I9: A2 | J9: 6 | K9: 2030 | L9: 4 | M9: FLEX | N9: Is on the NHS | O9: Tell City,Vincennes | P9: Dale Unit 4,Oakland City Unit | Q9: Spencer,Warrick | R9: 16956 | S9: 5780 | T9: N/A | U9: =IF($L9<=2, IF($R9<=RpmDesignStandard!$C$2,RpmDesignStandard!$D$2, IF(AND($R9>RpmDesignStandard!$B$3,$R9<=RpmDesignStandard!$C$3),RpmDesignStandard!$D$3,RpmDesignStandard!$D$4)), IF($R9<=RpmDesignStandard!$C$5, RpmDesignStandard!$D$5, IF(AND($R9>RpmDesignStandard!$B$6,$R9<=RpmDesignStandard!$C$6),RpmDesignStandard!$D$6, IF(AND($R9>RpmDesignStandard!$B$7,$R9<=RpmDesignStandard!$C$7),RpmDesignStandard!$D$7,RpmDesignStandard!$D$8)))) -> 3 | V9: =U9*RpmDesignStandard!$H$1 -> 6 | W9: =VLOOKUP(A9,RPM_ProjectRecord!A:AB,8,FALSE) | X9: =IFERROR(VALUE(LEFT(AE9,4)),"") -> 2030 | Y9: =IFERROR(VALUE(LEFT(AF9,4)),"") | Z9: =IFERROR(VALUE(LEFT(AG9,4)),"") | AA9: =IFERROR(VALUE(LEFT(AH9,4)),"") | AB9: =IFERROR(VALUE(LEFT(AI9,4)),"") | AC9: =IF(VLOOKUP(A9,'3rdPhaseChipSeal'!A:L,12,FALSE)="","",VLOOKUP(A9,'3rdPhaseChipSeal'!A:L,12,FALSE)) | AD9: =IFERROR(IF(VLOOKUP(A9,RpmContracts!A:C,3,FALSE)="","",VLOOKUP(A9,RpmContracts!A:C,3,FALSE)),"") -> 2027 | AE9: =IF(VLOOKUP(A9,'20yPlan'!A:B,2,FALSE)="","",VLOOKUP(A9,'20yPlan'!A:B,2,FALSE)) -> 2030 Minor Structural | AF9: =IF(VLOOKUP(A9,'20yPlan'!A:C,3,FALSE)="","",VLOOKUP(A9,'20yPlan'!A:C,3,FALSE)) | AG9: =IF(VLOOKUP(A9,'20yPlan'!A:D,4,FALSE)="","",VLOOKUP(A9,'20yPlan'!A:D,4,FALSE)) | AH9: =IF(VLOOKUP(A9,'20yPlan'!A:E,5,FALSE)="","",VLOOKUP(A9,'20yPlan'!A:E,5,FALSE)) | AI9: =IF(VLOOKUP(A9,'20yPlan'!A:F,6,FALSE)="","",VLOOKUP(A9,'20yPlan'!A:F,6,FALSE)) | AJ9: =IF(AC9="","",_xlfn.CONCAT(AC9," ","Chip Seal")) | AK9: =IF(AD9="","",_xlfn.CONCAT(AD9," ","RPM Replacement")) -> 2027 RPM Replacement | AL9: =IFERROR(U9+W9,YEAR(TODAY())) -> 2025 | AM9: =IF(W9="",AD9,IF(AND(MIN(X9:AD9)<=(W9+V9),MIN(X9:AD9)>W9),MIN(X9:AD9),"")) -> 2027 | AN9: =IF(AM9=X9,AE9,IF(AM9=Y9,AF9,IF(AM9=AC9,AJ9,AK9))) -> 2027 RPM Replacement
A10: 60008 | B10: I-64 | C10: From 0.79 Miles E of US 231 to 3.21 miles E of SR 162 | D10: 57.249264 | E10: 65.94863 | F10: 57 +0.254 | G10: 65 +0.924 | H10: 412860 | I10: A2 | J10: 6 | K10: 2035 | L10: 4 | M10: FLEX | N10: Is on the NHS | O10: Tell City | P10: Birdseye Unit 3,Chrisney Unit 5,Dale Unit 4 | Q10: Dubois,Spencer | R10: 16523 | S10: 6112 | T10: N/A | U10: =IF($L10<=2, IF($R10<=RpmDesignStandard!$C$2,RpmDesignStandard!$D$2, IF(AND($R10>RpmDesignStandard!$B$3,$R10<=RpmDesignStandard!$C$3),RpmDesignStandard!$D$3,RpmDesignStandard!$D$4)), IF($R10<=RpmDesignStandard!$C$5, RpmDesignStandard!$D$5, IF(AND($R10>RpmDesignStandard!$B$6,$R10<=RpmDesignStandard!$C$6),RpmDesignStandard!$D$6, IF(AND($R10>RpmDesignStandard!$B$7,$R10<=RpmDesignStandard!$C$7),RpmDesignStandard!$D$7,RpmDesignStandard!$D$8)))) -> 3 | V10: =U10*RpmDesignStandard!$H$1 -> 6 | W10: =VLOOKUP(A10,RPM_ProjectRecord!A:AB,8,FALSE) | X10: =IFERROR(VALUE(LEFT(AE10,4)),"") -> 2035 | Y10: =IFERROR(VALUE(LEFT(AF10,4)),"") | Z10: =IFERROR(VALUE(LEFT(AG10,4)),"") | AA10: =IFERROR(VALUE(LEFT(AH10,4)),"") | AB10: =IFERROR(VALUE(LEFT(AI10,4)),"") | AC10: =IF(VLOOKUP(A10,'3rdPhaseChipSeal'!A:L,12,FALSE)="","",VLOOKUP(A10,'3rdPhaseChipSeal'!A:L,12,FALSE)) | AD10: =IFERROR(IF(VLOOKUP(A10,RpmContracts!A:C,3,FALSE)="","",VLOOKUP(A10,RpmContracts!A:C,3,FALSE)),"") -> 2027 | AE10: =IF(VLOOKUP(A10,'20yPlan'!A:B,2,FALSE)="","",VLOOKUP(A10,'20yPlan'!A:B,2,FALSE)) -> 2035 Preventive Maintenance | AF10: =IF(VLOOKUP(A10,'20yPlan'!A:C,3,FALSE)="","",VLOOKUP(A10,'20yPlan'!A:C,3,FALSE)) | AG10: =IF(VLOOKUP(A10,'20yPlan'!A:D,4,FALSE)="","",VLOOKUP(A10,'20yPlan'!A:D,4,FALSE)) | AH10: =IF(VLOOKUP(A10,'20yPlan'!A:E,5,FALSE)="","",VLOOKUP(A10,'20yPlan'!A:E,5,FALSE)) | AI10: =IF(VLOOKUP(A10,'20yPlan'!A:F,6,FALSE)="","",VLOOKUP(A10,'20yPlan'!A:F,6,FALSE)) | AJ10: =IF(AC10="","",_xlfn.CONCAT(AC10," ","Chip Seal")) | AK10: =IF(AD10="","",_xlfn.CONCAT(AD10," ","RPM Replacement")) -> 2027 RPM Replacement | AL10: =IFERROR(U10+W10,YEAR(TODAY())) -> 2025 | AM10: =IF(W10="",AD10,IF(AND(MIN(X10:AD10)<=(W10+V10),MIN(X10:AD10)>W10),MIN(X10:AD10),"")) -> 2027 | AN10: =IF(AM10=X10,AE10,IF(AM10=Y10,AF10,IF(AM10=AC10,AJ10,AK10))) -> 2027 RPM Replacement
A11: 60009 | B11: I-64 | C11: From 3.21 miles E of SR 162 to 0.26 mi W of SR145 | D11: 65.94863 | E11: 71.729364 | F11: 65 +0.924 | G11: 71 +0.799 | H11: 278987 | I11: A2 | J11: 14 | K11: 2025 | L11: 4 | M11: FLEX | N11: Is on the NHS | O11: Tell City | P11: Birdseye Unit 3,Derby Unit 2 | Q11: Dubois,Perry,Spencer | R11: 17112 | S11: 5662 | T11: N/A | U11: =IF($L11<=2, IF($R11<=RpmDesignStandard!$C$2,RpmDesignStandard!$D$2, IF(AND($R11>RpmDesignStandard!$B$3,$R11<=RpmDesignStandard!$C$3),RpmDesignStandard!$D$3,RpmDesignStandard!$D$4)), IF($R11<=RpmDesignStandard!$C$5, RpmDesignStandard!$D$5, IF(AND($R11>RpmDesignStandard!$B$6,$R11<=RpmDesignStandard!$C$6),RpmDesignStandard!$D$6, IF(AND($R11>RpmDesignStandard!$B$7,$R11<=RpmDesignStandard!$C$7),RpmDesignStandard!$D$7,RpmDesignStandard!$D$8)))) -> 3 | V11: =U11*RpmDesignStandard!$H$1 -> 6 | W11: =VLOOKUP(A11,RPM_ProjectRecord!A:AB,8,FALSE) | X11: =IFERROR(VALUE(LEFT(AE11,4)),"") -> 2040 | Y11: =IFERROR(VALUE(LEFT(AF11,4)),"") | Z11: =IFERROR(VALUE(LEFT(AG11,4)),"") | AA11: =IFERROR(VALUE(LEFT(AH11,4)),"") | AB11: =IFERROR(VALUE(LEFT(AI11,4)),"") | AC11: =IF(VLOOKUP(A11,'3rdPhaseChipSeal'!A:L,12,FALSE)="","",VLOOKUP(A11,'3rdPhaseChipSeal'!A:L,12,FALSE)) | AD11: =IFERROR(IF(VLOOKUP(A11,RpmContracts!A:C,3,FALSE)="","",VLOOKUP(A11,RpmContracts!A:C,3,FALSE)),"") -> 2027 | AE11: =IF(VLOOKUP(A11,'20yPlan'!A:B,2,FALSE)="","",VLOOKUP(A11,'20yPlan'!A:B,2,FALSE)) -> 2040 Preventive Maintenance | AF11: =IF(VLOOKUP(A11,'20yPlan'!A:C,3,FALSE)="","",VLOOKUP(A11,'20yPlan'!A:C,3,FALSE)) | AG11: =IF(VLOOKUP(A11,'20yPlan'!A:D,4,FALSE)="","",VLOOKUP(A11,'20yPlan'!A:D,4,FALSE)) | AH11: =IF(VLOOKUP(A11,'20yPlan'!A:E,5,FALSE)="","",VLOOKUP(A11,'20yPlan'!A:E,5,FALSE)) | AI11: =IF(VLOOKUP(A11,'20yPlan'!A:F,6,FALSE)="","",VLOOKUP(A11,'20yPlan'!A:F,6,FALSE)) | AJ11: =IF(AC11="","",_xlfn.CONCAT(AC11," ","Chip Seal")) | AK11: =IF(AD11="","",_xlfn.CONCAT(AD11," ","RPM Replacement")) -> 2027 RPM Replacement | AL11: =IFERROR(U11+W11,YEAR(TODAY())) -> 2025 | AM11: =IF(W11="",AD11,IF(AND(MIN(X11:AD11)<=(W11+V11),MIN(X11:AD11)>W11),MIN(X11:AD11),"")) -> 2027 | AN11: =IF(AM11=X11,AE11,IF(AM11=Y11,AF11,IF(AM11=AC11,AJ11,AK11))) -> 2027 RPM Replacement
A12: 60010 | B12: I-64 | C12: From 0.26 mi W of SR145 to 0.47 Miles W of SR 37 | D12: 71.729364 | E12: 78.077108 | F12: 71 +0.799 | G12: 78 +0.137 | H12: 310405 | I12: A2 | J12: 6 | K12: 2034 | L12: 4 | M12: FLEX | N12: Is on the NHS | O12: Tell City | P12: Birdseye Unit 3,Derby Unit 2 | Q12: Crawford,Perry | R12: 16328 | S12: 6350 | T12: N/A | U12: =IF($L12<=2, IF($R12<=RpmDesignStandard!$C$2,RpmDesignStandard!$D$2, IF(AND($R12>RpmDesignStandard!$B$3,$R12<=RpmDesignStandard!$C$3),RpmDesignStandard!$D$3,RpmDesignStandard!$D$4)), IF($R12<=RpmDesignStandard!$C$5, RpmDesignStandard!$D$5, IF(AND($R12>RpmDesignStandard!$B$6,$R12<=RpmDesignStandard!$C$6),RpmDesignStandard!$D$6, IF(AND($R12>RpmDesignStandard!$B$7,$R12<=RpmDesignStandard!$C$7),RpmDesignStandard!$D$7,RpmDesignStandard!$D$8)))) -> 3 | V12: =U12*RpmDesignStandard!$H$1 -> 6 | W12: =VLOOKUP(A12,RPM_ProjectRecord!A:AB,8,FALSE) | X12: =IFERROR(VALUE(LEFT(AE12,4)),"") -> 2034 | Y12: =IFERROR(VALUE(LEFT(AF12,4)),"") | Z12: =IFERROR(VALUE(LEFT(AG12,4)),"") | AA12: =IFERROR(VALUE(LEFT(AH12,4)),"") | AB12: =IFERROR(VALUE(LEFT(AI12,4)),"") | AC12: =IF(VLOOKUP(A12,'3rdPhaseChipSeal'!A:L,12,FALSE)="","",VLOOKUP(A12,'3rdPhaseChipSeal'!A:L,12,FALSE)) | AD12: =IFERROR(IF(VLOOKUP(A12,RpmContracts!A:C,3,FALSE)="","",VLOOKUP(A12,RpmContracts!A:C,3,FALSE)),"") -> 2027 | AE12: =IF(VLOOKUP(A12,'20yPlan'!A:B,2,FALSE)="","",VLOOKUP(A12,'20yPlan'!A:B,2,FALSE)) -> 2034 Preventive Maintenance | AF12: =IF(VLOOKUP(A12,'20yPlan'!A:C,3,FALSE)="","",VLOOKUP(A12,'20yPlan'!A:C,3,FALSE)) | AG12: =IF(VLOOKUP(A12,'20yPlan'!A:D,4,FALSE)="","",VLOOKUP(A12,'20yPlan'!A:D,4,FALSE)) | AH12: =IF(VLOOKUP(A12,'20yPlan'!A:E,5,FALSE)="","",VLOOKUP(A12,'20yPlan'!A:E,5,FALSE)) | AI12: =IF(VLOOKUP(A12,'20yPlan'!A:F,6,FALSE)="","",VLOOKUP(A12,'20yPlan'!A:F,6,FALSE)) | AJ12: =IF(AC12="","",_xlfn.CONCAT(AC12," ","Chip Seal")) | AK12: =IF(AD12="","",_xlfn.CONCAT(AD12," ","RPM Replacement")) -> 2027 RPM Replacement | AL12: =IFERROR(U12+W12,YEAR(TODAY())) -> 2025 | AM12: =IF(W12="",AD12,IF(AND(MIN(X12:AD12)<=(W12+V12),MIN(X12:AD12)>W12),MIN(X12:AD12),"")) -> 2027 | AN12: =IF(AM12=X12,AE12,IF(AM12=Y12,AF12,IF(AM12=AC12,AJ12,AK12))) -> 2027 RPM Replacement
A13: 60011 | B13: I-64 | C13: From 0.47 Miles W of SR 37 to 1.30 Miles W of SR 237 | D13: 78.077108 | E13: 84.425189 | F13: 78 +0.137 | G13: 84 +0.504 | H13: 304464 | I13: A2 | J13: 7 | K13: 2031 | L13: 4 | M13: FLEX | N13: Is on the NHS | O13: Tell City | P13: Birdseye Unit 3 | Q13: Crawford,Perry | R13: 16917 | S13: 6712 | T13: N/A | U13: =IF($L13<=2, IF($R13<=RpmDesignStandard!$C$2,RpmDesignStandard!$D$2, IF(AND($R13>RpmDesignStandard!$B$3,$R13<=RpmDesignStandard!$C$3),RpmDesignStandard!$D$3,RpmDesignStandard!$D$4)), IF($R13<=RpmDesignStandard!$C$5, RpmDesignStandard!$D$5, IF(AND($R13>RpmDesignStandard!$B$6,$R13<=RpmDesignStandard!$C$6),RpmDesignStandard!$D$6, IF(AND($R13>RpmDesignStandard!$B$7,$R13<=RpmDesignStandard!$C$7),RpmDesignStandard!$D$7,RpmDesignStandard!$D$8)))) -> 3 | V13: =U13*RpmDesignStandard!$H$1 -> 6 | W13: =VLOOKUP(A13,RPM_ProjectRecord!A:AB,8,FALSE) | X13: =IFERROR(VALUE(LEFT(AE13,4)),"") -> 2031 | Y13: =IFERROR(VALUE(LEFT(AF13,4)),"") | Z13: =IFERROR(VALUE(LEFT(AG13,4)),"") | AA13: =IFERROR(VALUE(LEFT(AH13,4)),"") | AB13: =IFERROR(VALUE(LEFT(AI13,4)),"") | AC13: =IF(VLOOKUP(A13,'3rdPhaseChipSeal'!A:L,12,FALSE)="","",VLOOKUP(A13,'3rdPhaseChipSeal'!A:L,12,FALSE)) | AD13: =IFERROR(IF(VLOOKUP(A13,RpmContracts!A:C,3,FALSE)="","",VLOOKUP(A13,RpmContracts!A:C,3,FALSE)),"") -> 2027 | AE13: =IF(VLOOKUP(A13,'20yPlan'!A:B,2,FALSE)="","",VLOOKUP(A13,'20yPlan'!A:B,2,FALSE)) -> 2031 Preventive Maintenance | AF13: =IF(VLOOKUP(A13,'20yPlan'!A:C,3,FALSE)="","",VLOOKUP(A13,'20yPlan'!A:C,3,FALSE)) | AG13: =IF(VLOOKUP(A13,'20yPlan'!A:D,4,FALSE)="","",VLOOKUP(A13,'20yPlan'!A:D,4,FALSE)) | AH13: =IF(VLOOKUP(A13,'20yPlan'!A:E,5,FALSE)="","",VLOOKUP(A13,'20yPlan'!A:E,5,FALSE)) | AI13: =IF(VLOOKUP(A13,'20yPlan'!A:F,6,FALSE)="","",VLOOKUP(A13,'20yPlan'!A:F,6,FALSE)) | AJ13: =IF(AC13="","",_xlfn.CONCAT(AC13," ","Chip Seal")) | AK13: =IF(AD13="","",_xlfn.CONCAT(AD13," ","RPM Replacement")) -> 2027 RPM Replacement | AL13: =IFERROR(U13+W13,YEAR(TODAY())) -> 2025 | AM13: =IF(W13="",AD13,IF(AND(MIN(X13:AD13)<=(W13+V13),MIN(X13:AD13)>W13),MIN(X13:AD13),"")) -> 2027 | AN13: =IF(AM13=X13,AE13,IF(AM13=Y13,AF13,IF(AM13=AC13,AJ13,AK13))) -> 2027 RPM Replacement
... A22: 60020 | B22: I-69 | C22: From 6.62 mi N. US 50 to 3.12 mi S. SR 58 (Asphalt) | D22: 69.238749 | E22: 73.499573 | F22: 68 +0.556 | G22: 72 +0.818 | H22: 111443 | I22: A2 | J22: 11 | K22: 2027 | L22: 4 | M22: FLEX | N22: Is on the NHS | O22: Linton,Vincennes | P22: Linton,Loogootee Unit | Q22: Daviess | R22: 8895 | S22: 2383 | T22: N/A | U22: =IF($L22<=2, IF($R22<=RpmDesignStandard!$C$2,RpmDesignStandard!$D$2, IF(AND($R22>RpmDesignStandard!$B$3,$R22<=RpmDesignStandard!$C$3),RpmDesignStandard!$D$3,RpmDesignStandard!$D$4)), IF($R22<=RpmDesignStandard!$C$5, RpmDesignStandard!$D$5, IF(AND($R22>RpmDesignStandard!$B$6,$R22<=RpmDesignStandard!$C$6),RpmDesignStandard!$D$6, IF(AND($R22>RpmDesignStandard!$B$7,$R22<=RpmDesignStandard!$C$7),RpmDesignStandard!$D$7,RpmDesignStandard!$D$8)))) -> 4 | V22: =U22*RpmDesignStandard!$H$1 -> 8 | W22: =VLOOKUP(A22,RPM_ProjectRecord!A:AB,8,FALSE) | X22: =IFERROR(VALUE(LEFT(AE22,4)),"") -> 2042 | Y22: =IFERROR(VALUE(LEFT(AF22,4)),"") | Z22: =IFERROR(VALUE(LEFT(AG22,4)),"") | AA22: =IFERROR(VALUE(LEFT(AH22,4)),"") | AB22: =IFERROR(VALUE(LEFT(AI22,4)),"") | AC22: =IF(VLOOKUP(A22,'3rdPhaseChipSeal'!A:L,12,FALSE)="","",VLOOKUP(A22,'3rdPhaseChipSeal'!A:L,12,FALSE)) | AD22: =IFERROR(IF(VLOOKUP(A22,RpmContracts!A:C,3,FALSE)="","",VLOOKUP(A22,RpmContracts!A:C,3,FALSE)),"") -> 2027 | AE22: =IF(VLOOKUP(A22,'20yPlan'!A:B,2,FALSE)="","",VLOOKUP(A22,'20yPlan'!A:B,2,FALSE)) -> 2042 Preventive Maintenance | AF22: =IF(VLOOKUP(A22,'20yPlan'!A:C,3,FALSE)="","",VLOOKUP(A22,'20yPlan'!A:C,3,FALSE)) | AG22: =IF(VLOOKUP(A22,'20yPlan'!A:D,4,FALSE)="","",VLOOKUP(A22,'20yPlan'!A:D,4,FALSE)) | AH22: =IF(VLOOKUP(A22,'20yPlan'!A:E,5,FALSE)="","",VLOOKUP(A22,'20yPlan'!A:E,5,FALSE)) | AI22: =IF(VLOOKUP(A22,'20yPlan'!A:F,6,FALSE)="","",VLOOKUP(A22,'20yPlan'!A:F,6,FALSE)) | AJ22: =IF(AC22="","",_xlfn.CONCAT(AC22," ","Chip Seal")) | AK22: =IF(AD22="","",_xlfn.CONCAT(AD22," ","RPM Replacement")) -> 2027 RPM Replacement | AL22: =IFERROR(U22+W22,YEAR(TODAY())) -> 2025 | AM22: =IF(W22="",AD22,IF(AND(MIN(X22:AD22)<=(W22+V22),MIN(X22:AD22)>W22),MIN(X22:AD22),"")) -> 2027 | AN22: =IF(AM22=X22,AE22,IF(AM22=Y22,AF22,IF(AM22=AC22,AJ22,AK22))) -> 2027 RPM Replacement
A23: 60021 | B23: US 41 | C23: From KY /IN State line To 0.10 mi S. I69 | D23: 0 | E23: 1.057752 | F23: 0 -0.064 | G23: 1 +0.112 | H23: 53754 | I23: B1 | J23: 4 | L23: 4 | M23: FLEX | N23: Is on the NHS | O23: Evansville | P23: Evansville Unit 1 | Q23: Vanderburgh | R23: 38467 | S23: 5122 | T23: N/A | U23: =IF($L23<=2, IF($R23<=RpmDesignStandard!$C$2,RpmDesignStandard!$D$2, IF(AND($R23>RpmDesignStandard!$B$3,$R23<=RpmDesignStandard!$C$3),RpmDesignStandard!$D$3,RpmDesignStandard!$D$4)), IF($R23<=RpmDesignStandard!$C$5, RpmDesignStandard!$D$5, IF(AND($R23>RpmDesignStandard!$B$6,$R23<=RpmDesignStandard!$C$6),RpmDesignStandard!$D$6, IF(AND($R23>RpmDesignStandard!$B$7,$R23<=RpmDesignStandard!$C$7),RpmDesignStandard!$D$7,RpmDesignStandard!$D$8)))) -> 2 | V23: =U23*RpmDesignStandard!$H$1 -> 4 | W23: =VLOOKUP(A23,RPM_ProjectRecord!A:AB,8,FALSE) | X23: =IFERROR(VALUE(LEFT(AE23,4)),"") | Y23: =IFERROR(VALUE(LEFT(AF23,4)),"") | Z23: =IFERROR(VALUE(LEFT(AG23,4)),"") | AA23: =IFERROR(VALUE(LEFT(AH23,4)),"") | AB23: =IFERROR(VALUE(LEFT(AI23,4)),"") | AC23: =IF(VLOOKUP(A23,'3rdPhaseChipSeal'!A:L,12,FALSE)="","",VLOOKUP(A23,'3rdPhaseChipSeal'!A:L,12,FALSE)) | AD23: =IFERROR(IF(VLOOKUP(A23,RpmContracts!A:C,3,FALSE)="","",VLOOKUP(A23,RpmContracts!A:C,3,FALSE)),"") | AE23: =IF(VLOOKUP(A23,'20yPlan'!A:B,2,FALSE)="","",VLOOKUP(A23,'20yPlan'!A:B,2,FALSE)) | AF23: =IF(VLOOKUP(A23,'20yPlan'!A:C,3,FALSE)="","",VLOOKUP(A23,'20yPlan'!A:C,3,FALSE)) | AG23: =IF(VLOOKUP(A23,'20yPlan'!A:D,4,FALSE)="","",VLOOKUP(A23,'20yPlan'!A:D,4,FALSE)) | AH23: =IF(VLOOKUP(A23,'20yPlan'!A:E,5,FALSE)="","",VLOOKUP(A23,'20yPlan'!A:E,5,FALSE)) | AI23: =IF(VLOOKUP(A23,'20yPlan'!A:F,6,FALSE)="","",VLOOKUP(A23,'20yPlan'!A:F,6,FALSE)) | AJ23: =IF(AC23="","",_xlfn.CONCAT(AC23," ","Chip Seal")) | AK23: =IF(AD23="","",_xlfn.CONCAT(AD23," ","RPM Replacement")) | AL23: =IFERROR(U23+W23,YEAR(TODAY())) -> 2025 | AM23: =IF(W23="",AD23,IF(AND(MIN(X23:AD23)<=(W23+V23),MIN(X23:AD23)>W23),MIN(X23:AD23),"")) | AN23: =IF(AM23=X23,AE23,IF(AM23=Y23,AF23,IF(AM23=AC23,AJ23,AK23)))
A24: 60022 | B24: US 41 | C24: From SR 57 to 3.30 mi N SR-57 (0.20 mi N Boonville/New Harmony Road) | D24: 8.90409 | E24: 12.194726 | F24: 8 +0.646 | G24: 12 +0.248 | H24: 142320 | I24: B1 | J24: 6 | L24: 4 | M24: FLEX | N24: Is on the NHS | O24: Evansville | P24: Boyle Lane Unit 2 | Q24: Vanderburgh | R24: 25274 | S24: 3433 | T24: N/A | U24: =IF($L24<=2, IF($R24<=RpmDesignStandard!$C$2,RpmDesignStandard!$D$2, IF(AND($R24>RpmDesignStandard!$B$3,$R24<=RpmDesignStandard!$C$3),RpmDesignStandard!$D$3,RpmDesignStandard!$D$4)), IF($R24<=RpmDesignStandard!$C$5, RpmDesignStandard!$D$5, IF(AND($R24>RpmDesignStandard!$B$6,$R24<=RpmDesignStandard!$C$6),RpmDesignStandard!$D$6, IF(AND($R24>RpmDesignStandard!$B$7,$R24<=RpmDesignStandard!$C$7),RpmDesignStandard!$D$7,RpmDesignStandard!$D$8)))) -> 3 | V24: =U24*RpmDesignStandard!$H$1 -> 6 | W24: =VLOOKUP(A24,RPM_ProjectRecord!A:AB,8,FALSE) -> 2025 | X24: =IFERROR(VALUE(LEFT(AE24,4)),"") | Y24: =IFERROR(VALUE(LEFT(AF24,4)),"") | Z24: =IFERROR(VALUE(LEFT(AG24,4)),"") | AA24: =IFERROR(VALUE(LEFT(AH24,4)),"") | AB24: =IFERROR(VALUE(LEFT(AI24,4)),"") | AC24: =IF(VLOOKUP(A24,'3rdPhaseChipSeal'!A:L,12,FALSE)="","",VLOOKUP(A24,'3rdPhaseChipSeal'!A:L,12,FALSE)) | AD24: =IFERROR(IF(VLOOKUP(A24,RpmContracts!A:C,3,FALSE)="","",VLOOKUP(A24,RpmContracts!A:C,3,FALSE)),"") -> 2027 | AE24: =IF(VLOOKUP(A24,'20yPlan'!A:B,2,FALSE)="","",VLOOKUP(A24,'20yPlan'!A:B,2,FALSE)) | AF24: =IF(VLOOKUP(A24,'20yPlan'!A:C,3,FALSE)="","",VLOOKUP(A24,'20yPlan'!A:C,3,FALSE)) | AG24: =IF(VLOOKUP(A24,'20yPlan'!A:D,4,FALSE)="","",VLOOKUP(A24,'20yPlan'!A:D,4,FALSE)) | AH24: =IF(VLOOKUP(A24,'20yPlan'!A:E,5,FALSE)="","",VLOOKUP(A24,'20yPlan'!A:E,5,FALSE)) | AI24: =IF(VLOOKUP(A24,'20yPlan'!A:F,6,FALSE)="","",VLOOKUP(A24,'20yPlan'!A:F,6,FALSE)) | AJ24: =IF(AC24="","",_xlfn.CONCAT(AC24," ","Chip Seal")) | AK24: =IF(AD24="","",_xlfn.CONCAT(AD24," ","RPM Replacement")) -> 2027 RPM Replacement | AL24: =IFERROR(U24+W24,YEAR(TODAY())) -> 2028 | AM24: =IF(W24="",AD24,IF(AND(MIN(X24:AD24)<=(W24+V24),MIN(X24:AD24)>W24),MIN(X24:AD24),"")) -> 2027 | AN24: =IF(AM24=X24,AE24,IF(AM24=Y24,AF24,IF(AM24=AC24,AJ24,AK24))) -> 2027 RPM Replacement
A25: 60023 | B25: US 41 | C25: From 3.30 mi N SR-57 (0.20 mi N Boonville/New Harmony Road) to 0.85 mi S. SR 168 (0.20 mi N. Coal Mine Rd) | D25: 12.194726 | E25: 22.403544 | F25: 12 +0.248 | G25: 22 +0.354 | H25: 527969 | I25: B1 | J25: 8 | K25: 2027 | L25: 4 | M25: FLEX | N25: Is on the NHS | O25: Evansville,Vincennes | P25: Boyle Lane Unit 2,Oakland City Unit | Q25: Gibson,Vanderburgh | R25: 23678 | S25: 3386 | T25: N/A | U25: =IF($L25<=2, IF($R25<=RpmDesignStandard!$C$2,RpmDesignStandard!$D$2, IF(AND($R25>RpmDesignStandard!$B$3,$R25<=RpmDesignStandard!$C$3),RpmDesignStandard!$D$3,RpmDesignStandard!$D$4)), IF($R25<=RpmDesignStandard!$C$5, RpmDesignStandard!$D$5, IF(AND($R25>RpmDesignStandard!$B$6,$R25<=RpmDesignStandard!$C$6),RpmDesignStandard!$D$6, IF(AND($R25>RpmDesignStandard!$B$7,$R25<=RpmDesignStandard!$C$7),RpmDesignStandard!$D$7,RpmDesignStandard!$D$8)))) -> 3 | V25: =U25*RpmDesignStandard!$H$1 -> 6 | W25: =VLOOKUP(A25,RPM_ProjectRecord!A:AB,8,FALSE) | X25: =IFERROR(VALUE(LEFT(AE25,4)),"") -> 2030 | Y25: =IFERROR(VALUE(LEFT(AF25,4)),"") | Z25: =IFERROR(VALUE(LEFT(AG25,4)),"") | AA25: =IFERROR(VALUE(LEFT(AH25,4)),"") | AB25: =IFERROR(VALUE(LEFT(AI25,4)),"") | AC25: =IF(VLOOKUP(A25,'3rdPhaseChipSeal'!A:L,12,FALSE)="","",VLOOKUP(A25,'3rdPhaseChipSeal'!A:L,12,FALSE)) | AD25: =IFERROR(IF(VLOOKUP(A25,RpmContracts!A:C,3,FALSE)="","",VLOOKUP(A25,RpmContracts!A:C,3,FALSE)),"") | AE25: =IF(VLOOKUP(A25,'20yPlan'!A:B,2,FALSE)="","",VLOOKUP(A25,'20yPlan'!A:B,2,FALSE)) -> 2030 Major Structural | AF25: =IF(VLOOKUP(A25,'20yPlan'!A:C,3,FALSE)="","",VLOOKUP(A25,'20yPlan'!A:C,3,FALSE)) | AG25: =IF(VLOOKUP(A25,'20yPlan'!A:D,4,FALSE)="","",VLOOKUP(A25,'20yPlan'!A:D,4,FALSE)) | AH25: =IF(VLOOKUP(A25,'20yPlan'!A:E,5,FALSE)="","",VLOOKUP(A25,'20yPlan'!A:E,5,FALSE)) | AI25: =IF(VLOOKUP(A25,'20yPlan'!A:F,6,FALSE)="","",VLOOKUP(A25,'20yPlan'!A:F,6,FALSE)) | AJ25: =IF(AC25="","",_xlfn.CONCAT(AC25," ","Chip Seal")) | AK25: =IF(AD25="","",_xlfn.CONCAT(AD25," ","RPM Replacement")) | AL25: =IFERROR(U25+W25,YEAR(TODAY())) -> 2025 | AM25: =IF(W25="",AD25,IF(AND(MIN(X25:AD25)<=(W25+V25),MIN(X25:AD25)>W25),MIN(X25:AD25),"")) | AN25: =IF(AM25=X25,AE25,IF(AM25=Y25,AF25,IF(AM25=AC25,AJ25,AK25)))
A26: 60024 | B26: US 41 | C26: From 0.85 SR 168 ( 0.20 mil N. Coal Mine Rd) to 0.53 N. SR 64 (Southern RR Bridge) | D26: 22.403544 | E26: 31.516692 | F26: 22 +0.354 | G26: 31 +0.451 | H26: 406131 | I26: B1 | J26: 11 | K26: 2027 | L26: 4 | M26: FLEX | N26: Is on the NHS | O26: Evansville,Vincennes | P26: Boyle Lane Unit 2,Oakland City Unit,Vincennes Unit 2 | Q26: Gibson | R26: 19159 | S26: 2941 | T26: N/A | U26: =IF($L26<=2, IF($R26<=RpmDesignStandard!$C$2,RpmDesignStandard!$D$2, IF(AND($R26>RpmDesignStandard!$B$3,$R26<=RpmDesignStandard!$C$3),RpmDesignStandard!$D$3,RpmDesignStandard!$D$4)), IF($R26<=RpmDesignStandard!$C$5, RpmDesignStandard!$D$5, IF(AND($R26>RpmDesignStandard!$B$6,$R26<=RpmDesignStandard!$C$6),RpmDesignStandard!$D$6, IF(AND($R26>RpmDesignStandard!$B$7,$R26<=RpmDesignStandard!$C$7),RpmDesignStandard!$D$7,RpmDesignStandard!$D$8)))) -> 3 | V26: =U26*RpmDesignStandard!$H$1 -> 6 | W26: =VLOOKUP(A26,RPM_ProjectRecord!A:AB,8,FALSE) -> 2021 | X26: =IFERROR(VALUE(LEFT(AE26,4)),"") | Y26: =IFERROR(VALUE(LEFT(AF26,4)),"") | Z26: =IFERROR(VALUE(LEFT(AG26,4)),"") | AA26: =IFERROR(VALUE(LEFT(AH26,4)),"") | AB26: =IFERROR(VALUE(LEFT(AI26,4)),"") | AC26: =IF(VLOOKUP(A26,'3rdPhaseChipSeal'!A:L,12,FALSE)="","",VLOOKUP(A26,'3rdPhaseChipSeal'!A:L,12,FALSE)) | AD26: =IFERROR(IF(VLOOKUP(A26,RpmContracts!A:C,3,FALSE)="","",VLOOKUP(A26,RpmContracts!A:C,3,FALSE)),"") -> 2027 | AE26: =IF(VLOOKUP(A26,'20yPlan'!A:B,2,FALSE)="","",VLOOKUP(A26,'20yPlan'!A:B,2,FALSE)) | AF26: =IF(VLOOKUP(A26,'20yPlan'!A:C,3,FALSE)="","",VLOOKUP(A26,'20yPlan'!A:C,3,FALSE)) | AG26: =IF(VLOOKUP(A26,'20yPlan'!A:D,4,FALSE)="","",VLOOKUP(A26,'20yPlan'!A:D,4,FALSE)) | AH26: =IF(VLOOKUP(A26,'20yPlan'!A:E,5,FALSE)="","",VLOOKUP(A26,'20yPlan'!A:E,5,FALSE)) | AI26: =IF(VLOOKUP(A26,'20yPlan'!A:F,6,FALSE)="","",VLOOKUP(A26,'20yPlan'!A:F,6,FALSE)) | AJ26: =IF(AC26="","",_xlfn.CONCAT(AC26," ","Chip Seal")) | AK26: =IF(AD26="","",_xlfn.CONCAT(AD26," ","RPM Replacement")) -> 2027 RPM Replacement | AL26: =IFERROR(U26+W26,YEAR(TODAY())) -> 2024 | AM26: =IF(W26="",AD26,IF(AND(MIN(X26:AD26)<=(W26+V26),MIN(X26:AD26)>W26),MIN(X26:AD26),"")) -> 2027 | AN26: =IF(AM26=X26,AE26,IF(AM26=Y26,AF26,IF(AM26=AC26,AJ26,AK26))) -> 2027 RPM Replacement
A27: 60025 | B27: US 41 | C27: From 0.53 miles N of SR-64 to 0.50 miles S of SR-241 | D27: 31.516692 | E27: 43.178109 | F27: 31 +0.451 | G27: 43 +0.177 | H27: 513715 | I27: B2 | J27: 5 | L27: 4 | M27: FLEX | N27: Is on the NHS | O27: Vincennes | P27: Oakland City Unit,Vincennes Unit 2 | Q27: Gibson,Knox | R27: 11679 | S27: 1791 | T27: N/A | U27: =IF($L27<=2, IF($R27<=RpmDesignStandard!$C$2,RpmDesignStandard!$D$2, IF(AND($R27>RpmDesignStandard!$B$3,$R27<=RpmDesignStandard!$C$3),RpmDesignStandard!$D$3,RpmDesignStandard!$D$4)), IF($R27<=RpmDesignStandard!$C$5, RpmDesignStandard!$D$5, IF(AND($R27>RpmDesignStandard!$B$6,$R27<=RpmDesignStandard!$C$6),RpmDesignStandard!$D$6, IF(AND($R27>RpmDesignStandard!$B$7,$R27<=RpmDesignStandard!$C$7),RpmDesignStandard!$D$7,RpmDesignStandard!$D$8)))) -> 3 | V27: =U27*RpmDesignStandard!$H$1 -> 6 | W27: =VLOOKUP(A27,RPM_ProjectRecord!A:AB,8,FALSE) -> 2025 | X27: =IFERROR(VALUE(LEFT(AE27,4)),"") | Y27: =IFERROR(VALUE(LEFT(AF27,4)),"") | Z27: =IFERROR(VALUE(LEFT(AG27,4)),"") | AA27: =IFERROR(VALUE(LEFT(AH27,4)),"") | AB27: =IFERROR(VALUE(LEFT(AI27,4)),"") | AC27: =IF(VLOOKUP(A27,'3rdPhaseChipSeal'!A:L,12,FALSE)="","",VLOOKUP(A27,'3rdPhaseChipSeal'!A:L,12,FALSE)) | AD27: =IFERROR(IF(VLOOKUP(A27,RpmContracts!A:C,3,FALSE)="","",VLOOKUP(A27,RpmContracts!A:C,3,FALSE)),"") -> 2027 | AE27: =IF(VLOOKUP(A27,'20yPlan'!A:B,2,FALSE)="","",VLOOKUP(A27,'20yPlan'!A:B,2,FALSE)) | AF27: =IF(VLOOKUP(A27,'20yPlan'!A:C,3,FALSE)="","",VLOOKUP(A27,'20yPlan'!A:C,3,FALSE)) | AG27: =IF(VLOOKUP(A27,'20yPlan'!A:D,4,FALSE)="","",VLOOKUP(A27,'20yPlan'!A:D,4,FALSE)) | AH27: =IF(VLOOKUP(A27,'20yPlan'!A:E,5,FALSE)="","",VLOOKUP(A27,'20yPlan'!A:E,5,FALSE)) | AI27: =IF(VLOOKUP(A27,'20yPlan'!A:F,6,FALSE)="","",VLOOKUP(A27,'20yPlan'!A:F,6,FALSE)) | AJ27: =IF(AC27="","",_xlfn.CONCAT(AC27," ","Chip Seal")) | AK27: =IF(AD27="","",_xlfn.CONCAT(AD27," ","RPM Replacement")) -> 2027 RPM Replacement | AL27: =IFERROR(U27+W27,YEAR(TODAY())) -> 2028 | AM27: =IF(W27="",AD27,IF(AND(MIN(X27:AD27)<=(W27+V27),MIN(X27:AD27)>W27),MIN(X27:AD27),"")) -> 2027 | AN27: =IF(AM27=X27,AE27,IF(AM27=Y27,AF27,IF(AM27=AC27,AJ27,AK27))) -> 2027 RPM Replacement
A28: 60026 | B28: US 41 | C28: From 0.50 miles S of SR-241 to 0.58 mi S of E intersection with US 50 (Kelso Creek bridge) | D28: 43.178109 | E28: 54.736686 | F28: 43 +0.177 | G28: 54 +0.594 | H28: 543253 | I28: B2 | J28: 17 | K28: 2026 | L28: 4 | M28: FLEX | N28: Is on the NHS | O28: Vincennes | P28: Oakland City Unit,Vincennes Unit 2 | Q28: Gibson,Knox | R28: 13676 | S28: 2097 | T28: N/A | U28: =IF($L28<=2, IF($R28<=RpmDesignStandard!$C$2,RpmDesignStandard!$D$2, IF(AND($R28>RpmDesignStandard!$B$3,$R28<=RpmDesignStandard!$C$3),RpmDesignStandard!$D$3,RpmDesignStandard!$D$4)), IF($R28<=RpmDesignStandard!$C$5, RpmDesignStandard!$D$5, IF(AND($R28>RpmDesignStandard!$B$6,$R28<=RpmDesignStandard!$C$6),RpmDesignStandard!$D$6, IF(AND($R28>RpmDesignStandard!$B$7,$R28<=RpmDesignStandard!$C$7),RpmDesignStandard!$D$7,RpmDesignStandard!$D$8)))) -> 3 | V28: =U28*RpmDesignStandard!$H$1 -> 6 | W28: =VLOOKUP(A28,RPM_ProjectRecord!A:AB,8,FALSE) | X28: =IFERROR(VALUE(LEFT(AE28,4)),"") | Y28: =IFERROR(VALUE(LEFT(AF28,4)),"") | Z28: =IFERROR(VALUE(LEFT(AG28,4)),"") | AA28: =IFERROR(VALUE(LEFT(AH28,4)),"") | AB28: =IFERROR(VALUE(LEFT(AI28,4)),"") | AC28: =IF(VLOOKUP(A28,'3rdPhaseChipSeal'!A:L,12,FALSE)="","",VLOOKUP(A28,'3rdPhaseChipSeal'!A:L,12,FALSE)) | AD28: =IFERROR(IF(VLOOKUP(A28,RpmContracts!A:C,3,FALSE)="","",VLOOKUP(A28,RpmContracts!A:C,3,FALSE)),"") -> 2027 | AE28: =IF(VLOOKUP(A28,'20yPlan'!A:B,2,FALSE)="","",VLOOKUP(A28,'20yPlan'!A:B,2,FALSE)) | AF28: =IF(VLOOKUP(A28,'20yPlan'!A:C,3,FALSE)="","",VLOOKUP(A28,'20yPlan'!A:C,3,FALSE)) | AG28: =IF(VLOOKUP(A28,'20yPlan'!A:D,4,FALSE)="","",VLOOKUP(A28,'20yPlan'!A:D,4,FALSE)) | AH28: =IF(VLOOKUP(A28,'20yPlan'!A:E,5,FALSE)="","",VLOOKUP(A28,'20yPlan'!A:E,5,FALSE)) | AI28: =IF(VLOOKUP(A28,'20yPlan'!A:F,6,FALSE)="","",VLOOKUP(A28,'20yPlan'!A:F,6,FALSE)) | AJ28: =IF(AC28="","",_xlfn.CONCAT(AC28," ","Chip Seal")) | AK28: =IF(AD28="","",_xlfn.CONCAT(AD28," ","RPM Replacement")) -> 2027 RPM Replacement | AL28: =IFERROR(U28+W28,YEAR(TODAY())) -> 2025 | AM28: =IF(W28="",AD28,IF(AND(MIN(X28:AD28)<=(W28+V28),MIN(X28:AD28)>W28),MIN(X28:AD28),"")) -> 2027 | AN28: =IF(AM28=X28,AE28,IF(AM28=Y28,AF28,IF(AM28=AC28,AJ28,AK28))) -> 2027 RPM Replacement
A29: 60027 | B29: US 41 | C29: From W. Jct. US 50 to SR 550 | D29: 56.490668 | E29: 64.497228 | F29: 56 +0.155 | G29: 64 +0.433 | H29: 416914 | I29: B2 | J29: 15 | K29: 2028 | L29: 4 | M29: FLEX | N29: Is on the NHS | O29: Linton,Vincennes | P29: Sullivan Unit 3,Vincennes Unit 2 | Q29: Knox | R29: 10183 | S29: 1562 | T29: N/A | U29: =IF($L29<=2, IF($R29<=RpmDesignStandard!$C$2,RpmDesignStandard!$D$2, IF(AND($R29>RpmDesignStandard!$B$3,$R29<=RpmDesignStandard!$C$3),RpmDesignStandard!$D$3,RpmDesignStandard!$D$4)), IF($R29<=RpmDesignStandard!$C$5, RpmDesignStandard!$D$5, IF(AND($R29>RpmDesignStandard!$B$6,$R29<=RpmDesignStandard!$C$6),RpmDesignStandard!$D$6, IF(AND($R29>RpmDesignStandard!$B$7,$R29<=RpmDesignStandard!$C$7),RpmDesignStandard!$D$7,RpmDesignStandard!$D$8)))) -> 3 | V29: =U29*RpmDesignStandard!$H$1 -> 6 | W29: =VLOOKUP(A29,RPM_ProjectRecord!A:AB,8,FALSE) -> 2025 | X29: =IFERROR(VALUE(LEFT(AE29,4)),"") | Y29: =IFERROR(VALUE(LEFT(AF29,4)),"") | Z29: =IFERROR(VALUE(LEFT(AG29,4)),"") | AA29: =IFERROR(VALUE(LEFT(AH29,4)),"") | AB29: =IFERROR(VALUE(LEFT(AI29,4)),"") | AC29: =IF(VLOOKUP(A29,'3rdPhaseChipSeal'!A:L,12,FALSE)="","",VLOOKUP(A29,'3rdPhaseChipSeal'!A:L,12,FALSE)) | AD29: =IFERROR(IF(VLOOKUP(A29,RpmContracts!A:C,3,FALSE)="","",VLOOKUP(A29,RpmContracts!A:C,3,FALSE)),"") -> 2027 | AE29: =IF(VLOOKUP(A29,'20yPlan'!A:B,2,FALSE)="","",VLOOKUP(A29,'20yPlan'!A:B,2,FALSE)) | AF29: =IF(VLOOKUP(A29,'20yPlan'!A:C,3,FALSE)="","",VLOOKUP(A29,'20yPlan'!A:C,3,FALSE)) | AG29: =IF(VLOOKUP(A29,'20yPlan'!A:D,4,FALSE)="","",VLOOKUP(A29,'20yPlan'!A:D,4,FALSE)) | AH29: =IF(VLOOKUP(A29,'20yPlan'!A:E,5,FALSE)="","",VLOOKUP(A29,'20yPlan'!A:E,5,FALSE)) | AI29: =IF(VLOOKUP(A29,'20yPlan'!A:F,6,FALSE)="","",VLOOKUP(A29,'20yPlan'!A:F,6,FALSE)) | AJ29: =IF(AC29="","",_xlfn.CONCAT(AC29," ","Chip Seal")) | AK29: =IF(AD29="","",_xlfn.CONCAT(AD29," ","RPM Replacement")) -> 2027 RPM Replacement | AL29: =IFERROR(U29+W29,YEAR(TODAY())) -> 2028 | AM29: =IF(W29="",AD29,IF(AND(MIN(X29:AD29)<=(W29+V29),MIN(X29:AD29)>W29),MIN(X29:AD29),"")) -> 2027 | AN29: =IF(AM29=X29,AE29,IF(AM29=Y29,AF29,IF(AM29=AC29,AJ29,AK29))) -> 2027 RPM Replacement
A30: 60028 | B30: US 41 | C30: From SR 550 to 5.94 miles S of SR 58 (N. of Oaktown) | D30: 64.497228 | E30: 70.449892 | F30: 64 +0.433 | G30: 70 +0.490 | H30: 279906 | I30: B2 | J30: 15 | K30: 2030 | L30: 4 | M30: FLEX | N30: Is on the NHS | O30: Linton | P30: Sullivan Unit 3 | Q30: Knox | R30: 9109 | S30: 1397 | T30: N/A | U30: =IF($L30<=2, IF($R30<=RpmDesignStandard!$C$2,RpmDesignStandard!$D$2, IF(AND($R30>RpmDesignStandard!$B$3,$R30<=RpmDesignStandard!$C$3),RpmDesignStandard!$D$3,RpmDesignStandard!$D$4)), IF($R30<=RpmDesignStandard!$C$5, RpmDesignStandard!$D$5, IF(AND($R30>RpmDesignStandard!$B$6,$R30<=RpmDesignStandard!$C$6),RpmDesignStandard!$D$6, IF(AND($R30>RpmDesignStandard!$B$7,$R30<=RpmDesignStandard!$C$7),RpmDesignStandard!$D$7,RpmDesignStandard!$D$8)))) -> 4 | V30: =U30*RpmDesignStandard!$H$1 -> 8 | W30: =VLOOKUP(A30,RPM_ProjectRecord!A:AB,8,FALSE) -> 2025 | X30: =IFERROR(VALUE(LEFT(AE30,4)),"") -> 2030 | Y30: =IFERROR(VALUE(LEFT(AF30,4)),"") | Z30: =IFERROR(VALUE(LEFT(AG30,4)),"") | AA30: =IFERROR(VALUE(LEFT(AH30,4)),"") | AB30: =IFERROR(VALUE(LEFT(AI30,4)),"") | AC30: =IF(VLOOKUP(A30,'3rdPhaseChipSeal'!A:L,12,FALSE)="","",VLOOKUP(A30,'3rdPhaseChipSeal'!A:L,12,FALSE)) | AD30: =IFERROR(IF(VLOOKUP(A30,RpmContracts!A:C,3,FALSE)="","",VLOOKUP(A30,RpmContracts!A:C,3,FALSE)),"") -> 2027 | AE30: =IF(VLOOKUP(A30,'20yPlan'!A:B,2,FALSE)="","",VLOOKUP(A30,'20yPlan'!A:B,2,FALSE)) -> 2030 Preventive Maintenance | AF30: =IF(VLOOKUP(A30,'20yPlan'!A:C,3,FALSE)="","",VLOOKUP(A30,'20yPlan'!A:C,3,FALSE)) | AG30: =IF(VLOOKUP(A30,'20yPlan'!A:D,4,FALSE)="","",VLOOKUP(A30,'20yPlan'!A:D,4,FALSE)) | AH30: =IF(VLOOKUP(A30,'20yPlan'!A:E,5,FALSE)="","",VLOOKUP(A30,'20yPlan'!A:E,5,FALSE)) | AI30: =IF(VLOOKUP(A30,'20yPlan'!A:F,6,FALSE)="","",VLOOKUP(A30,'20yPlan'!A:F,6,FALSE)) | AJ30: =IF(AC30="","",_xlfn.CONCAT(AC30," ","Chip Seal")) | AK30: =IF(AD30="","",_xlfn.CONCAT(AD30," ","RPM Replacement")) -> 2027 RPM Replacement | AL30: =IFERROR(U30+W30,YEAR(TODAY())) -> 2029 | AM30: =IF(W30="",AD30,IF(AND(MIN(X30:AD30)<=(W30+V30),MIN(X30:AD30)>W30),MIN(X30:AD30),"")) -> 2027 | AN30: =IF(AM30=X30,AE30,IF(AM30=Y30,AF30,IF(AM30=AC30,AJ30,AK30))) -> 2027 RPM Replacement
A31: 60029 | B31: US 41 | C31: From 5.94 miles S of SR 58 (N. of Oaktown) to 0.44 mi S. SR 58 | D31: 70.449892 | E31: 75.819746 | F31: 70 +0.490 | G31: 75 +0.856 | H31: 247349 | I31: B2 | J31: 1 | L31: 4 | M31: FLEX | N31: Is on the NHS | O31: Linton | P31: Sullivan Unit 3 | Q31: Knox,Sullivan | R31: 8302 | S31: 1274 | T31: N/A | U31: =IF($L31<=2, IF($R31<=RpmDesignStandard!$C$2,RpmDesignStandard!$D$2, IF(AND($R31>RpmDesignStandard!$B$3,$R31<=RpmDesignStandard!$C$3),RpmDesignStandard!$D$3,RpmDesignStandard!$D$4)), IF($R31<=RpmDesignStandard!$C$5, RpmDesignStandard!$D$5, IF(AND($R31>RpmDesignStandard!$B$6,$R31<=RpmDesignStandard!$C$6),RpmDesignStandard!$D$6, IF(AND($R31>RpmDesignStandard!$B$7,$R31<=RpmDesignStandard!$C$7),RpmDesignStandard!$D$7,RpmDesignStandard!$D$8)))) -> 4 | V31: =U31*RpmDesignStandard!$H$1 -> 8 | W31: =VLOOKUP(A31,RPM_ProjectRecord!A:AB,8,FALSE) -> 2022 | X31: =IFERROR(VALUE(LEFT(AE31,4)),"") | Y31: =IFERROR(VALUE(LEFT(AF31,4)),"") | Z31: =IFERROR(VALUE(LEFT(AG31,4)),"") | AA31: =IFERROR(VALUE(LEFT(AH31,4)),"") | AB31: =IFERROR(VALUE(LEFT(AI31,4)),"") | AC31: =IF(VLOOKUP(A31,'3rdPhaseChipSeal'!A:L,12,FALSE)="","",VLOOKUP(A31,'3rdPhaseChipSeal'!A:L,12,FALSE)) | AD31: =IFERROR(IF(VLOOKUP(A31,RpmContracts!A:C,3,FALSE)="","",VLOOKUP(A31,RpmContracts!A:C,3,FALSE)),"") -> 2027 | AE31: =IF(VLOOKUP(A31,'20yPlan'!A:B,2,FALSE)="","",VLOOKUP(A31,'20yPlan'!A:B,2,FALSE)) | AF31: =IF(VLOOKUP(A31,'20yPlan'!A:C,3,FALSE)="","",VLOOKUP(A31,'20yPlan'!A:C,3,FALSE)) | AG31: =IF(VLOOKUP(A31,'20yPlan'!A:D,4,FALSE)="","",VLOOKUP(A31,'20yPlan'!A:D,4,FALSE)) | AH31: =IF(VLOOKUP(A31,'20yPlan'!A:E,5,FALSE)="","",VLOOKUP(A31,'20yPlan'!A:E,5,FALSE)) | AI31: =IF(VLOOKUP(A31,'20yPlan'!A:F,6,FALSE)="","",VLOOKUP(A31,'20yPlan'!A:F,6,FALSE)) | AJ31: =IF(AC31="","",_xlfn.CONCAT(AC31," ","Chip Seal")) | AK31: =IF(AD31="","",_xlfn.CONCAT(AD31," ","RPM Replacement")) -> 2027 RPM Replacement | AL31: =IFERROR(U31+W31,YEAR(TODAY())) -> 2026 | AM31: =IF(W31="",AD31,IF(AND(MIN(X31:AD31)<=(W31+V31),MIN(X31:AD31)>W31),MIN(X31:AD31),"")) -> 2027 | AN31: =IF(AM31=X31,AE31,IF(AM31=Y31,AF31,IF(AM31=AC31,AJ31,AK31))) -> 2027 RPM Replacement
A32: 60030 | B32: US 41 | C32: From 0.44 mi S. SR 58 to 0.47 mi N of SR 54 at RR | D32: 75.819746 | E32: 84.495275 | F32: 75 +0.856 | G32: 84 +0.570 | H32: 397884 | I32: B2 | J32: 17 | L32: 4 | M32: FLEX | N32: Is on the NHS | O32: Linton | P32: Sullivan Unit 3 | Q32: Sullivan | R32: 9801 | S32: 1503 | T32: N/A | U32: =IF($L32<=2, IF($R32<=RpmDesignStandard!$C$2,RpmDesignStandard!$D$2, IF(AND($R32>RpmDesignStandard!$B$3,$R32<=RpmDesignStandard!$C$3),RpmDesignStandard!$D$3,RpmDesignStandard!$D$4)), IF($R32<=RpmDesignStandard!$C$5, RpmDesignStandard!$D$5, IF(AND($R32>RpmDesignStandard!$B$6,$R32<=RpmDesignStandard!$C$6),RpmDesignStandard!$D$6, IF(AND($R32>RpmDesignStandard!$B$7,$R32<=RpmDesignStandard!$C$7),RpmDesignStandard!$D$7,RpmDesignStandard!$D$8)))) -> 4 | V32: =U32*RpmDesignStandard!$H$1 -> 8 | W32: =VLOOKUP(A32,RPM_ProjectRecord!A:AB,8,FALSE) | X32: =IFERROR(VALUE(LEFT(AE32,4)),"") | Y32: =IFERROR(VALUE(LEFT(AF32,4)),"") | Z32: =IFERROR(VALUE(LEFT(AG32,4)),"") | AA32: =IFERROR(VALUE(LEFT(AH32,4)),"") | AB32: =IFERROR(VALUE(LEFT(AI32,4)),"") | AC32: =IF(VLOOKUP(A32,'3rdPhaseChipSeal'!A:L,12,FALSE)="","",VLOOKUP(A32,'3rdPhaseChipSeal'!A:L,12,FALSE)) | AD32: =IFERROR(IF(VLOOKUP(A32,RpmContracts!A:C,3,FALSE)="","",VLOOKUP(A32,RpmContracts!A:C,3,FALSE)),"") -> 2027 | AE32: =IF(VLOOKUP(A32,'20yPlan'!A:B,2,FALSE)="","",VLOOKUP(A32,'20yPlan'!A:B,2,FALSE)) | AF32: =IF(VLOOKUP(A32,'20yPlan'!A:C,3,FALSE)="","",VLOOKUP(A32,'20yPlan'!A:C,3,FALSE)) | AG32: =IF(VLOOKUP(A32,'20yPlan'!A:D,4,FALSE)="","",VLOOKUP(A32,'20yPlan'!A:D,4,FALSE)) | AH32: =IF(VLOOKUP(A32,'20yPlan'!A:E,5,FALSE)="","",VLOOKUP(A32,'20yPlan'!A:E,5,FALSE)) | AI32: =IF(VLOOKUP(A32,'20yPlan'!A:F,6,FALSE)="","",VLOOKUP(A32,'20yPlan'!A:F,6,FALSE)) | AJ32: =IF(AC32="","",_xlfn.CONCAT(AC32," ","Chip Seal")) | AK32: =IF(AD32="","",_xlfn.CONCAT(AD32," ","RPM Replacement")) -> 2027 RPM Replacement | AL32: =IFERROR(U32+W32,YEAR(TODAY())) -> 2025 | AM32: =IF(W32="",AD32,IF(AND(MIN(X32:AD32)<=(W32+V32),MIN(X32:AD32)>W32),MIN(X32:AD32),"")) -> 2027 | AN32: =IF(AM32=X32,AE32,IF(AM32=Y32,AF32,IF(AM32=AC32,AJ32,AK32))) -> 2027 RPM Replacement
A33: 60031 | B33: US 41 | C33: From 0.47 mi N of SR 54 at RR to 1.64 miles S of SR 48 | D33: 84.495275 | E33: 90.74209 | F33: 84 +0.570 | G33: 90 +0.793 | H33: 292217 | I33: B2 | J33: 9 | L33: 4 | M33: FLEX | N33: Is on the NHS | O33: Linton | P33: Sullivan Unit 3 | Q33: Sullivan | R33: 12706 | S33: 1948 | T33: N/A | U33: =IF($L33<=2, IF($R33<=RpmDesignStandard!$C$2,RpmDesignStandard!$D$2, IF(AND($R33>RpmDesignStandard!$B$3,$R33<=RpmDesignStandard!$C$3),RpmDesignStandard!$D$3,RpmDesignStandard!$D$4)), IF($R33<=RpmDesignStandard!$C$5, RpmDesignStandard!$D$5, IF(AND($R33>RpmDesignStandard!$B$6,$R33<=RpmDesignStandard!$C$6),RpmDesignStandard!$D$6, IF(AND($R33>RpmDesignStandard!$B$7,$R33<=RpmDesignStandard!$C$7),RpmDesignStandard!$D$7,RpmDesignStandard!$D$8)))) -> 3 | V33: =U33*RpmDesignStandard!$H$1 -> 6 | W33: =VLOOKUP(A33,RPM_ProjectRecord!A:AB,8,FALSE) | X33: =IFERROR(VALUE(LEFT(AE33,4)),"") | Y33: =IFERROR(VALUE(LEFT(AF33,4)),"") | Z33: =IFERROR(VALUE(LEFT(AG33,4)),"") | AA33: =IFERROR(VALUE(LEFT(AH33,4)),"") | AB33: =IFERROR(VALUE(LEFT(AI33,4)),"") | AC33: =IF(VLOOKUP(A33,'3rdPhaseChipSeal'!A:L,12,FALSE)="","",VLOOKUP(A33,'3rdPhaseChipSeal'!A:L,12,FALSE)) | AD33: =IFERROR(IF(VLOOKUP(A33,RpmContracts!A:C,3,FALSE)="","",VLOOKUP(A33,RpmContracts!A:C,3,FALSE)),"") -> 2027 | AE33: =IF(VLOOKUP(A33,'20yPlan'!A:B,2,FALSE)="","",VLOOKUP(A33,'20yPlan'!A:B,2,FALSE)) | AF33: =IF(VLOOKUP(A33,'20yPlan'!A:C,3,FALSE)="","",VLOOKUP(A33,'20yPlan'!A:C,3,FALSE)) | AG33: =IF(VLOOKUP(A33,'20yPlan'!A:D,4,FALSE)="","",VLOOKUP(A33,'20yPlan'!A:D,4,FALSE)) | AH33: =IF(VLOOKUP(A33,'20yPlan'!A:E,5,FALSE)="","",VLOOKUP(A33,'20yPlan'!A:E,5,FALSE)) | AI33: =IF(VLOOKUP(A33,'20yPlan'!A:F,6,FALSE)="","",VLOOKUP(A33,'20yPlan'!A:F,6,FALSE)) | AJ33: =IF(AC33="","",_xlfn.CONCAT(AC33," ","Chip Seal")) | AK33: =IF(AD33="","",_xlfn.CONCAT(AD33," ","RPM Replacement")) -> 2027 RPM Replacement | AL33: =IFERROR(U33+W33,YEAR(TODAY())) -> 2025 | AM33: =IF(W33="",AD33,IF(AND(MIN(X33:AD33)<=(W33+V33),MIN(X33:AD33)>W33),MIN(X33:AD33),"")) -> 2027 | AN33: =IF(AM33=X33,AE33,IF(AM33=Y33,AF33,IF(AM33=AC33,AJ33,AK33))) -> 2027 RPM Replacement
A34: 60032 | B34: US 41 | C34: From 1.64 miles S of SR 48 to SR 246 | D34: 90.74209 | E34: 98.53665 | F34: 90 +0.793 | G34: 98 +0.616 | H34: 364439 | I34: B2 | J34: 5 | L34: 4 | M34: FLEX | N34: Is on the NHS | O34: Linton | P34: Sullivan Unit 3 | Q34: Sullivan,Vigo | R34: 15749 | S34: 2415 | T34: N/A | U34: =IF($L34<=2, IF($R34<=RpmDesignStandard!$C$2,RpmDesignStandard!$D$2, IF(AND($R34>RpmDesignStandard!$B$3,$R34<=RpmDesignStandard!$C$3),RpmDesignStandard!$D$3,RpmDesignStandard!$D$4)), IF($R34<=RpmDesignStandard!$C$5, RpmDesignStandard!$D$5, IF(AND($R34>RpmDesignStandard!$B$6,$R34<=RpmDesignStandard!$C$6),RpmDesignStandard!$D$6, IF(AND($R34>RpmDesignStandard!$B$7,$R34<=RpmDesignStandard!$C$7),RpmDesignStandard!$D$7,RpmDesignStandard!$D$8)))) -> 3 | V34: =U34*RpmDesignStandard!$H$1 -> 6 | W34: =VLOOKUP(A34,RPM_ProjectRecord!A:AB,8,FALSE) | X34: =IFERROR(VALUE(LEFT(AE34,4)),"") | Y34: =IFERROR(VALUE(LEFT(AF34,4)),"") | Z34: =IFERROR(VALUE(LEFT(AG34,4)),"") | AA34: =IFERROR(VALUE(LEFT(AH34,4)),"") | AB34: =IFERROR(VALUE(LEFT(AI34,4)),"") | AC34: =IF(VLOOKUP(A34,'3rdPhaseChipSeal'!A:L,12,FALSE)="","",VLOOKUP(A34,'3rdPhaseChipSeal'!A:L,12,FALSE)) | AD34: =IFERROR(IF(VLOOKUP(A34,RpmContracts!A:C,3,FALSE)="","",VLOOKUP(A34,RpmContracts!A:C,3,FALSE)),"") -> 2027 | AE34: =IF(VLOOKUP(A34,'20yPlan'!A:B,2,FALSE)="","",VLOOKUP(A34,'20yPlan'!A:B,2,FALSE)) | AF34: =IF(VLOOKUP(A34,'20yPlan'!A:C,3,FALSE)="","",VLOOKUP(A34,'20yPlan'!A:C,3,FALSE)) | AG34: =IF(VLOOKUP(A34,'20yPlan'!A:D,4,FALSE)="","",VLOOKUP(A34,'20yPlan'!A:D,4,FALSE)) | AH34: =IF(VLOOKUP(A34,'20yPlan'!A:E,5,FALSE)="","",VLOOKUP(A34,'20yPlan'!A:E,5,FALSE)) | AI34: =IF(VLOOKUP(A34,'20yPlan'!A:F,6,FALSE)="","",VLOOKUP(A34,'20yPlan'!A:F,6,FALSE)) | AJ34: =IF(AC34="","",_xlfn.CONCAT(AC34," ","Chip Seal")) | AK34: =IF(AD34="","",_xlfn.CONCAT(AD34," ","RPM Replacement")) -> 2027 RPM Replacement | AL34: =IFERROR(U34+W34,YEAR(TODAY())) -> 2025 | AM34: =IF(W34="",AD34,IF(AND(MIN(X34:AD34)<=(W34+V34),MIN(X34:AD34)>W34),MIN(X34:AD34),"")) -> 2027 | AN34: =IF(AM34=X34,AE34,IF(AM34=Y34,AF34,IF(AM34=AC34,AJ34,AK34))) -> 2027 RPM Replacement
A35: 60033 | B35: US 50 | C35: From IL/IN State Line to US 41/6th St | D35: 0 | E35: 1.862243 | F35: 0 +0.000 | G35: 1 +0.844 | H35: 87060 | I35: B2 | J35: 1 | L35: 4 | M35: FLEX | N35: Is on the NHS | O35: Vincennes | P35: Vincennes Unit 2 | Q35: Knox | R35: 6107 | S35: 1020 | T35: N/A | U35: =IF($L35<=2, IF($R35<=RpmDesignStandard!$C$2,RpmDesignStandard!$D$2, IF(AND($R35>RpmDesignStandard!$B$3,$R35<=RpmDesignStandard!$C$3),RpmDesignStandard!$D$3,RpmDesignStandard!$D$4)), IF($R35<=RpmDesignStandard!$C$5, RpmDesignStandard!$D$5, IF(AND($R35>RpmDesignStandard!$B$6,$R35<=RpmDesignStandard!$C$6),RpmDesignStandard!$D$6, IF(AND($R35>RpmDesignStandard!$B$7,$R35<=RpmDesignStandard!$C$7),RpmDesignStandard!$D$7,RpmDesignStandard!$D$8)))) -> 4 | V35: =U35*RpmDesignStandard!$H$1 -> 8 | W35: =VLOOKUP(A35,RPM_ProjectRecord!A:AB,8,FALSE) -> 2022 | X35: =IFERROR(VALUE(LEFT(AE35,4)),"") | Y35: =IFERROR(VALUE(LEFT(AF35,4)),"") | Z35: =IFERROR(VALUE(LEFT(AG35,4)),"") | AA35: =IFERROR(VALUE(LEFT(AH35,4)),"") | AB35: =IFERROR(VALUE(LEFT(AI35,4)),"") | AC35: =IF(VLOOKUP(A35,'3rdPhaseChipSeal'!A:L,12,FALSE)="","",VLOOKUP(A35,'3rdPhaseChipSeal'!A:L,12,FALSE)) | AD35: =IFERROR(IF(VLOOKUP(A35,RpmContracts!A:C,3,FALSE)="","",VLOOKUP(A35,RpmContracts!A:C,3,FALSE)),"") | AE35: =IF(VLOOKUP(A35,'20yPlan'!A:B,2,FALSE)="","",VLOOKUP(A35,'20yPlan'!A:B,2,FALSE)) | AF35: =IF(VLOOKUP(A35,'20yPlan'!A:C,3,FALSE)="","",VLOOKUP(A35,'20yPlan'!A:C,3,FALSE)) | AG35: =IF(VLOOKUP(A35,'20yPlan'!A:D,4,FALSE)="","",VLOOKUP(A35,'20yPlan'!A:D,4,FALSE)) | AH35: =IF(VLOOKUP(A35,'20yPlan'!A:E,5,FALSE)="","",VLOOKUP(A35,'20yPlan'!A:E,5,FALSE)) | AI35: =IF(VLOOKUP(A35,'20yPlan'!A:F,6,FALSE)="","",VLOOKUP(A35,'20yPlan'!A:F,6,FALSE)) | AJ35: =IF(AC35="","",_xlfn.CONCAT(AC35," ","Chip Seal")) | AK35: =IF(AD35="","",_xlfn.CONCAT(AD35," ","RPM Replacement")) | AL35: =IFERROR(U35+W35,YEAR(TODAY())) -> 2026 | AM35: =IF(W35="",AD35,IF(AND(MIN(X35:AD35)<=(W35+V35),MIN(X35:AD35)>W35),MIN(X35:AD35),"")) | AN35: =IF(AM35=X35,AE35,IF(AM35=Y35,AF35,IF(AM35=AC35,AJ35,AK35)))
A36: 60034 | B36: US 50 | C36: From 4.47 E. of E. Jct. US 41 to W. Of White River Bridge | D36: 6.610016 | E36: 16.186454 | F36: 7 +0.462 | G36: 17 +0.168 | H36: 433802 | I36: B2 | J36: 13 | L36: 4 | M36: RIGID | N36: Is on the NHS | O36: Vincennes | P36: Oakland City Unit,Vincennes Unit 2 | Q36: Daviess,Knox | R36: 8395 | S36: 1413 | T36: N/A | U36: =IF($L36<=2, IF($R36<=RpmDesignStandard!$C$2,RpmDesignStandard!$D$2, IF(AND($R36>RpmDesignStandard!$B$3,$R36<=RpmDesignStandard!$C$3),RpmDesignStandard!$D$3,RpmDesignStandard!$D$4)), IF($R36<=RpmDesignStandard!$C$5, RpmDesignStandard!$D$5, IF(AND($R36>RpmDesignStandard!$B$6,$R36<=RpmDesignStandard!$C$6),RpmDesignStandard!$D$6, IF(AND($R36>RpmDesignStandard!$B$7,$R36<=RpmDesignStandard!$C$7),RpmDesignStandard!$D$7,RpmDesignStandard!$D$8)))) -> 4 | V36: =U36*RpmDesignStandard!$H$1 -> 8 | W36: =VLOOKUP(A36,RPM_ProjectRecord!A:AB,8,FALSE) | X36: =IFERROR(VALUE(LEFT(AE36,4)),"") | Y36: =IFERROR(VALUE(LEFT(AF36,4)),"") | Z36: =IFERROR(VALUE(LEFT(AG36,4)),"") | AA36: =IFERROR(VALUE(LEFT(AH36,4)),"") | AB36: =IFERROR(VALUE(LEFT(AI36,4)),"") | AC36: =IF(VLOOKUP(A36,'3rdPhaseChipSeal'!A:L,12,FALSE)="","",VLOOKUP(A36,'3rdPhaseChipSeal'!A:L,12,FALSE)) | AD36: =IFERROR(IF(VLOOKUP(A36,RpmContracts!A:C,3,FALSE)="","",VLOOKUP(A36,RpmContracts!A:C,3,FALSE)),"") -> 2027 | AE36: =IF(VLOOKUP(A36,'20yPlan'!A:B,2,FALSE)="","",VLOOKUP(A36,'20yPlan'!A:B,2,FALSE)) | AF36: =IF(VLOOKUP(A36,'20yPlan'!A:C,3,FALSE)="","",VLOOKUP(A36,'20yPlan'!A:C,3,FALSE)) | AG36: =IF(VLOOKUP(A36,'20yPlan'!A:D,4,FALSE)="","",VLOOKUP(A36,'20yPlan'!A:D,4,FALSE)) | AH36: =IF(VLOOKUP(A36,'20yPlan'!A:E,5,FALSE)="","",VLOOKUP(A36,'20yPlan'!A:E,5,FALSE)) | AI36: =IF(VLOOKUP(A36,'20yPlan'!A:F,6,FALSE)="","",VLOOKUP(A36,'20yPlan'!A:F,6,FALSE)) | AJ36: =IF(AC36="","",_xlfn.CONCAT(AC36," ","Chip Seal")) | AK36: =IF(AD36="","",_xlfn.CONCAT(AD36," ","RPM Replacement")) -> 2027 RPM Replacement | AL36: =IFERROR(U36+W36,YEAR(TODAY())) -> 2025 | AM36: =IF(W36="",AD36,IF(AND(MIN(X36:AD36)<=(W36+V36),MIN(X36:AD36)>W36),MIN(X36:AD36),"")) -> 2027 | AN36: =IF(AM36=X36,AE36,IF(AM36=Y36,AF36,IF(AM36=AC36,AJ36,AK36))) -> 2027 RPM Replacement
